Workbook
Name EmpNames: OFFSET(الموظفات!$B$5,0,0,MAX(1,COUNTA(الموظفات!$B$5:$B$304)),1)
Name FieldList: OFFSET(الإعدادات!$A$7,0,0,COUNTA(الإعدادات!$A$7:$A$35),1)
Name LevelList: الإعدادات!$K$7:$K$8
Name CatList: الإعدادات!$L$7:$L$8
Name StatusList: الإعدادات!$M$7:$M$8
Name ReportTypes: الإعدادات!$N$7:$N$9
Name YearList: OFFSET(الإعدادات!$O$7,0,0,COUNTA(الإعدادات!$O$7:$O$30),1)
Name SemList: الإعدادات!$P$7:$P$8
Name RewardList: OFFSET(الإعدادات!$Q$7,0,0,COUNTA(الإعدادات!$Q$7:$Q$60),1)
Name NomList: OFFSET(الإعدادات!$R$7,0,0,COUNTA(الإعدادات!$R$7:$R$60),1)
Name MonthNames: الإعدادات!$H$7:$H$18
Name CritKey: المعايير!$A$5:$A$332

Sheet دليل الاستخدام
A1: نظام تسجيل التحفيز — رائدات المستقبل 2026-2027
A2: مدرسة هند بنت عتبة الإعدادية للبنات · مديرة المدرسة: حصة الشمري · النائبة الأكاديمية: إيناس العوضي · النائبة الإدارية: مريم المري
A4: # | B4: الصفحة | C4: طريقة الاستخدام
A5: 1 | B5: الموظفات | C5: قائمة الموظفات (149) منقولة من كشف المدرسة. أضيفي الرقم الوظيفي في العمود A — يظهر في السجل والتقارير تلقائيًا ولا يظهر في واجهة التطبيق.
A6: 2 | B6: سجل التحفيز | C6: الأعمدة A إلى J للإدخال (أو اللصق من التطبيق)، والأعمدة الرمادية من K تُحسب تلقائيًا: الرقم الوظيفي، المسمى، القسم، المكافأة وفق السياسة، الشهر، الفصل، السنة.
A7: 3 | B7: اللصق من التطبيق | C7: من التطبيق: «تصدير إلى إكسل» ← افتحي الملف ← انسخي الصفوف من الصف 2 ← الصقي في الخلية A5 من «سجل التحفيز» (لصق القيم). التصدير يشمل كل السجلات، فالصقي فوق القديم في كل مرة.
A8: 4 | B8: التقارير الجاهزة | C8: صفحة لكل شهر من سبتمبر إلى مايو، وصفحة للفصل الأول (سبتمبر–ديسمبر) وللفصل الثاني (يناير–مايو) مع توزيع شهري. كلها للسنة الدراسية الحالية في «الإعدادات».
A9: 5 | B9: التقارير (مخصص) | C9: اختاري السنة ونوع التقرير (شهري / فصلي / سنوي) والشهر أو الفصل لأي فترة أخرى.
A10: 6 | B10: لوحة السنة | C10: مصفوفة المجالات × الأشهر للسنة المختارة في صفحة «التقارير» مع رسم بياني شهري.
A11: ★ | B11: أمري تدللي | C11: من تجمع 5 معايير ذهبية في السنة الدراسية تُعلَّم «مستحقة ★» في صفحة الموظفات، ما لم تكن حالتها «محرومة» (مخالفة التعاميم).
B14: دليل الألوان
C15: خلية إدخال — تكتبين أو تختارين منها
C16: خلية تلقائية — لا تُعدَّل (معادلة)
C17: موظفة مستحقة لكوبون أمري تدللي

Sheet سجل التحفيز
A1: سجل التحفيز — قاعدة البيانات
A2: الأعمدة الصفراء A–J للإدخال أو للصق من التطبيق (لصق القيم بدءًا من A5). الأعمدة الرمادية تلقائية من صفحة الموظفات والإعدادات.
A4: التاريخ | B4: اسم الموظفة | C4: المجال | D4: مستوى المعيار | E4: المعيار المحقق | F4: المكافأة الممنوحة | G4: القيمة المادية (ر.ق) | H4: المُرشِّحة / الجهة | I4: أدلة التوثيق | J4: ملاحظات | K4: الرقم الوظيفي | L4: المسمى الوظيفي | M4: القسم | N4: الفئة | O4: المكافأة وفق السياسة | P4: الشهر | Q4: الفصل الدراسي | R4: السنة الدراسية | S4: ضمن التقرير | T4: تسلسل التقرير | U4: تسلسل: تقرير الفصل الأول | V4: تسلسل: تقرير الفصل الثاني | W4: تسلسل: تقرير سبتمبر | X4: تسلسل: تقرير أكتوبر | Y4: تسلسل: تقرير نوفمبر | Z4: تسلسل: تقرير ديسمبر | AA4: تسلسل: تقرير يناير | AB4: تسلسل: تقرير فبراير | AC4: تسلسل: تقرير مارس | AD4: تسلسل: تقرير أبريل | AE4: تسلسل: تقرير مايو
K5: =IF($B5="","",IFERROR(INDEX(الموظفات!$A$5:$A$304,MATCH($B5,الموظفات!$B$5:$B$304,0))&"","")) | L5: =IF($B5="","",IFERROR(INDEX(الموظفات!$C$5:$C$304,MATCH($B5,الموظفات!$B$5:$B$304,0))&"","")) | M5: =IF($B5="","",IFERROR(INDEX(الموظفات!$D$5:$D$304,MATCH($B5,الموظفات!$B$5:$B$304,0))&"","")) | N5: =IF($B5="","",IFERROR(INDEX(الموظفات!$E$5:$E$304,MATCH($B5,الموظفات!$B$5:$B$304,0))&"","")) | O5: =IF(C5="","",IFERROR(INDEX(الإعدادات!$D$7:$D$35,MATCH(C5,الإعدادات!$A$7:$A$35,0))&"","")) | P5: =IF(A5="","",INDEX(الإعدادات!$H$7:$H$18,MONTH(A5))) | Q5: =IF(A5="","",INDEX(الإعدادات!$I$7:$I$18,MONTH(A5))) | R5: =IF(A5="","",IF(MONTH(A5)>=8,YEAR(A5)&"-"&(YEAR(A5)+1),(YEAR(A5)-1)&"-"&YEAR(A5))) | S5: =IF(OR(A5="",B5=""),0,IF(AND(R5=التقارير!$C$4,OR(التقارير!$C$5="سنوي",AND(التقارير!$C$5="شهري",P5=التقارير!$C$6),AND(التقارير!$C$5="فصلي",Q5=التقارير!$C$7))),1,0)) | T5: =IF(S5=1,COUNTIF($S$5:S5,1),"") | U5: =IF(AND($A5<>"",$B5<>"",$R5='تقرير الفصل الأول'!$C$4,$Q5='تقرير الفصل الأول'!$C$7),COUNT(U$4:U4)+1,"") | V5: =IF(AND($A5<>"",$B5<>"",$R5='تقرير الفصل الثاني'!$C$4,$Q5='تقرير الفصل الثاني'!$C$7),COUNT(V$4:V4)+1,"") | W5: =IF(AND($A5<>"",$B5<>"",$R5='تقرير سبتمبر'!$C$4,$P5='تقرير سبتمبر'!$C$6),COUNT(W$4:W4)+1,"") | X5: =IF(AND($A5<>"",$B5<>"",$R5='تقرير أكتوبر'!$C$4,$P5='تقرير أكتوبر'!$C$6),COUNT(X$4:X4)+1,"") | Y5: =IF(AND($A5<>"",$B5<>"",$R5='تقرير نوفمبر'!$C$4,$P5='تقرير نوفمبر'!$C$6),COUNT(Y$4:Y4)+1,"") | Z5: =IF(AND($A5<>"",$B5<>"",$R5='تقرير ديسمبر'!$C$4,$P5='تقرير ديسمبر'!$C$6),COUNT(Z$4:Z4)+1,"") | AA5: =IF(AND($A5<>"",$B5<>"",$R5='تقرير يناير'!$C$4,$P5='تقرير يناير'!$C$6),COUNT(AA$4:AA4)+1,"") | AB5: =IF(AND($A5<>"",$B5<>"",$R5='تقرير فبراير'!$C$4,$P5='تقرير فبراير'!$C$6),COUNT(AB$4:AB4)+1,"") | AC5: =IF(AND($A5<>"",$B5<>"",$R5='تقرير مارس'!$C$4,$P5='تقرير مارس'!$C$6),COUNT(AC$4:AC4)+1,"") | AD5: =IF(AND($A5<>"",$B5<>"",$R5='تقرير أبريل'!$C$4,$P5='تقرير أبريل'!$C$6),COUNT(AD$4:AD4)+1,"") | AE5: =IF(AND($A5<>"",$B5<>"",$R5='تقرير مايو'!$C$4,$P5='تقرير مايو'!$C$6),COUNT(AE$4:AE4)+1,"")
K6: =IF($B6="","",IFERROR(INDEX(الموظفات!$A$5:$A$304,MATCH($B6,الموظفات!$B$5:$B$304,0))&"","")) | L6: =IF($B6="","",IFERROR(INDEX(الموظفات!$C$5:$C$304,MATCH($B6,الموظفات!$B$5:$B$304,0))&"","")) | M6: =IF($B6="","",IFERROR(INDEX(الموظفات!$D$5:$D$304,MATCH($B6,الموظفات!$B$5:$B$304,0))&"","")) | N6: =IF($B6="","",IFERROR(INDEX(الموظفات!$E$5:$E$304,MATCH($B6,الموظفات!$B$5:$B$304,0))&"","")) | O6: =IF(C6="","",IFERROR(INDEX(الإعدادات!$D$7:$D$35,MATCH(C6,الإعدادات!$A$7:$A$35,0))&"","")) | P6: =IF(A6="","",INDEX(الإعدادات!$H$7:$H$18,MONTH(A6))) | Q6: =IF(A6="","",INDEX(الإعدادات!$I$7:$I$18,MONTH(A6))) | R6: =IF(A6="","",IF(MONTH(A6)>=8,YEAR(A6)&"-"&(YEAR(A6)+1),(YEAR(A6)-1)&"-"&YEAR(A6))) | S6: =IF(OR(A6="",B6=""),0,IF(AND(R6=التقارير!$C$4,OR(التقارير!$C$5="سنوي",AND(التقارير!$C$5="شهري",P6=التقارير!$C$6),AND(التقارير!$C$5="فصلي",Q6=التقارير!$C$7))),1,0)) | T6: =IF(S6=1,COUNTIF($S$5:S6,1),"") | U6: =IF(AND($A6<>"",$B6<>"",$R6='تقرير الفصل الأول'!$C$4,$Q6='تقرير الفصل الأول'!$C$7),COUNT(U$4:U5)+1,"") | V6: =IF(AND($A6<>"",$B6<>"",$R6='تقرير الفصل الثاني'!$C$4,$Q6='تقرير الفصل الثاني'!$C$7),COUNT(V$4:V5)+1,"") | W6: =IF(AND($A6<>"",$B6<>"",$R6='تقرير سبتمبر'!$C$4,$P6='تقرير سبتمبر'!$C$6),COUNT(W$4:W5)+1,"") | X6: =IF(AND($A6<>"",$B6<>"",$R6='تقرير أكتوبر'!$C$4,$P6='تقرير أكتوبر'!$C$6),COUNT(X$4:X5)+1,"") | Y6: =IF(AND($A6<>"",$B6<>"",$R6='تقرير نوفمبر'!$C$4,$P6='تقرير نوفمبر'!$C$6),COUNT(Y$4:Y5)+1,"") | Z6: =IF(AND($A6<>"",$B6<>"",$R6='تقرير ديسمبر'!$C$4,$P6='تقرير ديسمبر'!$C$6),COUNT(Z$4:Z5)+1,"") | AA6: =IF(AND($A6<>"",$B6<>"",$R6='تقرير يناير'!$C$4,$P6='تقرير يناير'!$C$6),COUNT(AA$4:AA5)+1,"") | AB6: =IF(AND($A6<>"",$B6<>"",$R6='تقرير فبراير'!$C$4,$P6='تقرير فبراير'!$C$6),COUNT(AB$4:AB5)+1,"") | AC6: =IF(AND($A6<>"",$B6<>"",$R6='تقرير مارس'!$C$4,$P6='تقرير مارس'!$C$6),COUNT(AC$4:AC5)+1,"") | AD6: =IF(AND($A6<>"",$B6<>"",$R6='تقرير أبريل'!$C$4,$P6='تقرير أبريل'!$C$6),COUNT(AD$4:AD5)+1,"") | AE6: =IF(AND($A6<>"",$B6<>"",$R6='تقرير مايو'!$C$4,$P6='تقرير مايو'!$C$6),COUNT(AE$4:AE5)+1,"")
K7: =IF($B7="","",IFERROR(INDEX(الموظفات!$A$5:$A$304,MATCH($B7,الموظفات!$B$5:$B$304,0))&"","")) | L7: =IF($B7="","",IFERROR(INDEX(الموظفات!$C$5:$C$304,MATCH($B7,الموظفات!$B$5:$B$304,0))&"","")) | M7: =IF($B7="","",IFERROR(INDEX(الموظفات!$D$5:$D$304,MATCH($B7,الموظفات!$B$5:$B$304,0))&"","")) | N7: =IF($B7="","",IFERROR(INDEX(الموظفات!$E$5:$E$304,MATCH($B7,الموظفات!$B$5:$B$304,0))&"","")) | O7: =IF(C7="","",IFERROR(INDEX(الإعدادات!$D$7:$D$35,MATCH(C7,الإعدادات!$A$7:$A$35,0))&"","")) | P7: =IF(A7="","",INDEX(الإعدادات!$H$7:$H$18,MONTH(A7))) | Q7: =IF(A7="","",INDEX(الإعدادات!$I$7:$I$18,MONTH(A7))) | R7: =IF(A7="","",IF(MONTH(A7)>=8,YEAR(A7)&"-"&(YEAR(A7)+1),(YEAR(A7)-1)&"-"&YEAR(A7))) | S7: =IF(OR(A7="",B7=""),0,IF(AND(R7=التقارير!$C$4,OR(التقارير!$C$5="سنوي",AND(التقارير!$C$5="شهري",P7=التقارير!$C$6),AND(التقارير!$C$5="فصلي",Q7=التقارير!$C$7))),1,0)) | T7: =IF(S7=1,COUNTIF($S$5:S7,1),"") | U7: =IF(AND($A7<>"",$B7<>"",$R7='تقرير الفصل الأول'!$C$4,$Q7='تقرير الفصل الأول'!$C$7),COUNT(U$4:U6)+1,"") | V7: =IF(AND($A7<>"",$B7<>"",$R7='تقرير الفصل الثاني'!$C$4,$Q7='تقرير الفصل الثاني'!$C$7),COUNT(V$4:V6)+1,"") | W7: =IF(AND($A7<>"",$B7<>"",$R7='تقرير سبتمبر'!$C$4,$P7='تقرير سبتمبر'!$C$6),COUNT(W$4:W6)+1,"") | X7: =IF(AND($A7<>"",$B7<>"",$R7='تقرير أكتوبر'!$C$4,$P7='تقرير أكتوبر'!$C$6),COUNT(X$4:X6)+1,"") | Y7: =IF(AND($A7<>"",$B7<>"",$R7='تقرير نوفمبر'!$C$4,$P7='تقرير نوفمبر'!$C$6),COUNT(Y$4:Y6)+1,"") | Z7: =IF(AND($A7<>"",$B7<>"",$R7='تقرير ديسمبر'!$C$4,$P7='تقرير ديسمبر'!$C$6),COUNT(Z$4:Z6)+1,"") | AA7: =IF(AND($A7<>"",$B7<>"",$R7='تقرير يناير'!$C$4,$P7='تقرير يناير'!$C$6),COUNT(AA$4:AA6)+1,"") | AB7: =IF(AND($A7<>"",$B7<>"",$R7='تقرير فبراير'!$C$4,$P7='تقرير فبراير'!$C$6),COUNT(AB$4:AB6)+1,"") | AC7: =IF(AND($A7<>"",$B7<>"",$R7='تقرير مارس'!$C$4,$P7='تقرير مارس'!$C$6),COUNT(AC$4:AC6)+1,"") | AD7: =IF(AND($A7<>"",$B7<>"",$R7='تقرير أبريل'!$C$4,$P7='تقرير أبريل'!$C$6),COUNT(AD$4:AD6)+1,"") | AE7: =IF(AND($A7<>"",$B7<>"",$R7='تقرير مايو'!$C$4,$P7='تقرير مايو'!$C$6),COUNT(AE$4:AE6)+1,"")
K8: =IF($B8="","",IFERROR(INDEX(الموظفات!$A$5:$A$304,MATCH($B8,الموظفات!$B$5:$B$304,0))&"","")) | L8: =IF($B8="","",IFERROR(INDEX(الموظفات!$C$5:$C$304,MATCH($B8,الموظفات!$B$5:$B$304,0))&"","")) | M8: =IF($B8="","",IFERROR(INDEX(الموظفات!$D$5:$D$304,MATCH($B8,الموظفات!$B$5:$B$304,0))&"","")) | N8: =IF($B8="","",IFERROR(INDEX(الموظفات!$E$5:$E$304,MATCH($B8,الموظفات!$B$5:$B$304,0))&"","")) | O8: =IF(C8="","",IFERROR(INDEX(الإعدادات!$D$7:$D$35,MATCH(C8,الإعدادات!$A$7:$A$35,0))&"","")) | P8: =IF(A8="","",INDEX(الإعدادات!$H$7:$H$18,MONTH(A8))) | Q8: =IF(A8="","",INDEX(الإعدادات!$I$7:$I$18,MONTH(A8))) | R8: =IF(A8="","",IF(MONTH(A8)>=8,YEAR(A8)&"-"&(YEAR(A8)+1),(YEAR(A8)-1)&"-"&YEAR(A8))) | S8: =IF(OR(A8="",B8=""),0,IF(AND(R8=التقارير!$C$4,OR(التقارير!$C$5="سنوي",AND(التقارير!$C$5="شهري",P8=التقارير!$C$6),AND(التقارير!$C$5="فصلي",Q8=التقارير!$C$7))),1,0)) | T8: =IF(S8=1,COUNTIF($S$5:S8,1),"") | U8: =IF(AND($A8<>"",$B8<>"",$R8='تقرير الفصل الأول'!$C$4,$Q8='تقرير الفصل الأول'!$C$7),COUNT(U$4:U7)+1,"") | V8: =IF(AND($A8<>"",$B8<>"",$R8='تقرير الفصل الثاني'!$C$4,$Q8='تقرير الفصل الثاني'!$C$7),COUNT(V$4:V7)+1,"") | W8: =IF(AND($A8<>"",$B8<>"",$R8='تقرير سبتمبر'!$C$4,$P8='تقرير سبتمبر'!$C$6),COUNT(W$4:W7)+1,"") | X8: =IF(AND($A8<>"",$B8<>"",$R8='تقرير أكتوبر'!$C$4,$P8='تقرير أكتوبر'!$C$6),COUNT(X$4:X7)+1,"") | Y8: =IF(AND($A8<>"",$B8<>"",$R8='تقرير نوفمبر'!$C$4,$P8='تقرير نوفمبر'!$C$6),COUNT(Y$4:Y7)+1,"") | Z8: =IF(AND($A8<>"",$B8<>"",$R8='تقرير ديسمبر'!$C$4,$P8='تقرير ديسمبر'!$C$6),COUNT(Z$4:Z7)+1,"") | AA8: =IF(AND($A8<>"",$B8<>"",$R8='تقرير يناير'!$C$4,$P8='تقرير يناير'!$C$6),COUNT(AA$4:AA7)+1,"") | AB8: =IF(AND($A8<>"",$B8<>"",$R8='تقرير فبراير'!$C$4,$P8='تقرير فبراير'!$C$6),COUNT(AB$4:AB7)+1,"") | AC8: =IF(AND($A8<>"",$B8<>"",$R8='تقرير مارس'!$C$4,$P8='تقرير مارس'!$C$6),COUNT(AC$4:AC7)+1,"") | AD8: =IF(AND($A8<>"",$B8<>"",$R8='تقرير أبريل'!$C$4,$P8='تقرير أبريل'!$C$6),COUNT(AD$4:AD7)+1,"") | AE8: =IF(AND($A8<>"",$B8<>"",$R8='تقرير مايو'!$C$4,$P8='تقرير مايو'!$C$6),COUNT(AE$4:AE7)+1,"")
K9: =IF($B9="","",IFERROR(INDEX(الموظفات!$A$5:$A$304,MATCH($B9,الموظفات!$B$5:$B$304,0))&"","")) | L9: =IF($B9="","",IFERROR(INDEX(الموظفات!$C$5:$C$304,MATCH($B9,الموظفات!$B$5:$B$304,0))&"","")) | M9: =IF($B9="","",IFERROR(INDEX(الموظفات!$D$5:$D$304,MATCH($B9,الموظفات!$B$5:$B$304,0))&"","")) | N9: =IF($B9="","",IFERROR(INDEX(الموظفات!$E$5:$E$304,MATCH($B9,الموظفات!$B$5:$B$304,0))&"","")) | O9: =IF(C9="","",IFERROR(INDEX(الإعدادات!$D$7:$D$35,MATCH(C9,الإعدادات!$A$7:$A$35,0))&"","")) | P9: =IF(A9="","",INDEX(الإعدادات!$H$7:$H$18,MONTH(A9))) | Q9: =IF(A9="","",INDEX(الإعدادات!$I$7:$I$18,MONTH(A9))) | R9: =IF(A9="","",IF(MONTH(A9)>=8,YEAR(A9)&"-"&(YEAR(A9)+1),(YEAR(A9)-1)&"-"&YEAR(A9))) | S9: =IF(OR(A9="",B9=""),0,IF(AND(R9=التقارير!$C$4,OR(التقارير!$C$5="سنوي",AND(التقارير!$C$5="شهري",P9=التقارير!$C$6),AND(التقارير!$C$5="فصلي",Q9=التقارير!$C$7))),1,0)) | T9: =IF(S9=1,COUNTIF($S$5:S9,1),"") | U9: =IF(AND($A9<>"",$B9<>"",$R9='تقرير الفصل الأول'!$C$4,$Q9='تقرير الفصل الأول'!$C$7),COUNT(U$4:U8)+1,"") | V9: =IF(AND($A9<>"",$B9<>"",$R9='تقرير الفصل الثاني'!$C$4,$Q9='تقرير الفصل الثاني'!$C$7),COUNT(V$4:V8)+1,"") | W9: =IF(AND($A9<>"",$B9<>"",$R9='تقرير سبتمبر'!$C$4,$P9='تقرير سبتمبر'!$C$6),COUNT(W$4:W8)+1,"") | X9: =IF(AND($A9<>"",$B9<>"",$R9='تقرير أكتوبر'!$C$4,$P9='تقرير أكتوبر'!$C$6),COUNT(X$4:X8)+1,"") | Y9: =IF(AND($A9<>"",$B9<>"",$R9='تقرير نوفمبر'!$C$4,$P9='تقرير نوفمبر'!$C$6),COUNT(Y$4:Y8)+1,"") | Z9: =IF(AND($A9<>"",$B9<>"",$R9='تقرير ديسمبر'!$C$4,$P9='تقرير ديسمبر'!$C$6),COUNT(Z$4:Z8)+1,"") | AA9: =IF(AND($A9<>"",$B9<>"",$R9='تقرير يناير'!$C$4,$P9='تقرير يناير'!$C$6),COUNT(AA$4:AA8)+1,"") | AB9: =IF(AND($A9<>"",$B9<>"",$R9='تقرير فبراير'!$C$4,$P9='تقرير فبراير'!$C$6),COUNT(AB$4:AB8)+1,"") | AC9: =IF(AND($A9<>"",$B9<>"",$R9='تقرير مارس'!$C$4,$P9='تقرير مارس'!$C$6),COUNT(AC$4:AC8)+1,"") | AD9: =IF(AND($A9<>"",$B9<>"",$R9='تقرير أبريل'!$C$4,$P9='تقرير أبريل'!$C$6),COUNT(AD$4:AD8)+1,"") | AE9: =IF(AND($A9<>"",$B9<>"",$R9='تقرير مايو'!$C$4,$P9='تقرير مايو'!$C$6),COUNT(AE$4:AE8)+1,"")
K10: =IF($B10="","",IFERROR(INDEX(الموظفات!$A$5:$A$304,MATCH($B10,الموظفات!$B$5:$B$304,0))&"","")) | L10: =IF($B10="","",IFERROR(INDEX(الموظفات!$C$5:$C$304,MATCH($B10,الموظفات!$B$5:$B$304,0))&"","")) | M10: =IF($B10="","",IFERROR(INDEX(الموظفات!$D$5:$D$304,MATCH($B10,الموظفات!$B$5:$B$304,0))&"","")) | N10: =IF($B10="","",IFERROR(INDEX(الموظفات!$E$5:$E$304,MATCH($B10,الموظفات!$B$5:$B$304,0))&"","")) | O10: =IF(C10="","",IFERROR(INDEX(الإعدادات!$D$7:$D$35,MATCH(C10,الإعدادات!$A$7:$A$35,0))&"","")) | P10: =IF(A10="","",INDEX(الإعدادات!$H$7:$H$18,MONTH(A10))) | Q10: =IF(A10="","",INDEX(الإعدادات!$I$7:$I$18,MONTH(A10))) | R10: =IF(A10="","",IF(MONTH(A10)>=8,YEAR(A10)&"-"&(YEAR(A10)+1),(YEAR(A10)-1)&"-"&YEAR(A10))) | S10: =IF(OR(A10="",B10=""),0,IF(AND(R10=التقارير!$C$4,OR(التقارير!$C$5="سنوي",AND(التقارير!$C$5="شهري",P10=التقارير!$C$6),AND(التقارير!$C$5="فصلي",Q10=التقارير!$C$7))),1,0)) | T10: =IF(S10=1,COUNTIF($S$5:S10,1),"") | U10: =IF(AND($A10<>"",$B10<>"",$R10='تقرير الفصل الأول'!$C$4,$Q10='تقرير الفصل الأول'!$C$7),COUNT(U$4:U9)+1,"") | V10: =IF(AND($A10<>"",$B10<>"",$R10='تقرير الفصل الثاني'!$C$4,$Q10='تقرير الفصل الثاني'!$C$7),COUNT(V$4:V9)+1,"") | W10: =IF(AND($A10<>"",$B10<>"",$R10='تقرير سبتمبر'!$C$4,$P10='تقرير سبتمبر'!$C$6),COUNT(W$4:W9)+1,"") | X10: =IF(AND($A10<>"",$B10<>"",$R10='تقرير أكتوبر'!$C$4,$P10='تقرير أكتوبر'!$C$6),COUNT(X$4:X9)+1,"") | Y10: =IF(AND($A10<>"",$B10<>"",$R10='تقرير نوفمبر'!$C$4,$P10='تقرير نوفمبر'!$C$6),COUNT(Y$4:Y9)+1,"") | Z10: =IF(AND($A10<>"",$B10<>"",$R10='تقرير ديسمبر'!$C$4,$P10='تقرير ديسمبر'!$C$6),COUNT(Z$4:Z9)+1,"") | AA10: =IF(AND($A10<>"",$B10<>"",$R10='تقرير يناير'!$C$4,$P10='تقرير يناير'!$C$6),COUNT(AA$4:AA9)+1,"") | AB10: =IF(AND($A10<>"",$B10<>"",$R10='تقرير فبراير'!$C$4,$P10='تقرير فبراير'!$C$6),COUNT(AB$4:AB9)+1,"") | AC10: =IF(AND($A10<>"",$B10<>"",$R10='تقرير مارس'!$C$4,$P10='تقرير مارس'!$C$6),COUNT(AC$4:AC9)+1,"") | AD10: =IF(AND($A10<>"",$B10<>"",$R10='تقرير أبريل'!$C$4,$P10='تقرير أبريل'!$C$6),COUNT(AD$4:AD9)+1,"") | AE10: =IF(AND($A10<>"",$B10<>"",$R10='تقرير مايو'!$C$4,$P10='تقرير مايو'!$C$6),COUNT(AE$4:AE9)+1,"")
K11: =IF($B11="","",IFERROR(INDEX(الموظفات!$A$5:$A$304,MATCH($B11,الموظفات!$B$5:$B$304,0))&"","")) | L11: =IF($B11="","",IFERROR(INDEX(الموظفات!$C$5:$C$304,MATCH($B11,الموظفات!$B$5:$B$304,0))&"","")) | M11: =IF($B11="","",IFERROR(INDEX(الموظفات!$D$5:$D$304,MATCH($B11,الموظفات!$B$5:$B$304,0))&"","")) | N11: =IF($B11="","",IFERROR(INDEX(الموظفات!$E$5:$E$304,MATCH($B11,الموظفات!$B$5:$B$304,0))&"","")) | O11: =IF(C11="","",IFERROR(INDEX(الإعدادات!$D$7:$D$35,MATCH(C11,الإعدادات!$A$7:$A$35,0))&"","")) | P11: =IF(A11="","",INDEX(الإعدادات!$H$7:$H$18,MONTH(A11))) | Q11: =IF(A11="","",INDEX(الإعدادات!$I$7:$I$18,MONTH(A11))) | R11: =IF(A11="","",IF(MONTH(A11)>=8,YEAR(A11)&"-"&(YEAR(A11)+1),(YEAR(A11)-1)&"-"&YEAR(A11))) | S11: =IF(OR(A11="",B11=""),0,IF(AND(R11=التقارير!$C$4,OR(التقارير!$C$5="سنوي",AND(التقارير!$C$5="شهري",P11=التقارير!$C$6),AND(التقارير!$C$5="فصلي",Q11=التقارير!$C$7))),1,0)) | T11: =IF(S11=1,COUNTIF($S$5:S11,1),"") | U11: =IF(AND($A11<>"",$B11<>"",$R11='تقرير الفصل الأول'!$C$4,$Q11='تقرير الفصل الأول'!$C$7),COUNT(U$4:U10)+1,"") | V11: =IF(AND($A11<>"",$B11<>"",$R11='تقرير الفصل الثاني'!$C$4,$Q11='تقرير الفصل الثاني'!$C$7),COUNT(V$4:V10)+1,"") | W11: =IF(AND($A11<>"",$B11<>"",$R11='تقرير سبتمبر'!$C$4,$P11='تقرير سبتمبر'!$C$6),COUNT(W$4:W10)+1,"") | X11: =IF(AND($A11<>"",$B11<>"",$R11='تقرير أكتوبر'!$C$4,$P11='تقرير أكتوبر'!$C$6),COUNT(X$4:X10)+1,"") | Y11: =IF(AND($A11<>"",$B11<>"",$R11='تقرير نوفمبر'!$C$4,$P11='تقرير نوفمبر'!$C$6),COUNT(Y$4:Y10)+1,"") | Z11: =IF(AND($A11<>"",$B11<>"",$R11='تقرير ديسمبر'!$C$4,$P11='تقرير ديسمبر'!$C$6),COUNT(Z$4:Z10)+1,"") | AA11: =IF(AND($A11<>"",$B11<>"",$R11='تقرير يناير'!$C$4,$P11='تقرير يناير'!$C$6),COUNT(AA$4:AA10)+1,"") | AB11: =IF(AND($A11<>"",$B11<>"",$R11='تقرير فبراير'!$C$4,$P11='تقرير فبراير'!$C$6),COUNT(AB$4:AB10)+1,"") | AC11: =IF(AND($A11<>"",$B11<>"",$R11='تقرير مارس'!$C$4,$P11='تقرير مارس'!$C$6),COUNT(AC$4:AC10)+1,"") | AD11: =IF(AND($A11<>"",$B11<>"",$R11='تقرير أبريل'!$C$4,$P11='تقرير أبريل'!$C$6),COUNT(AD$4:AD10)+1,"") | AE11: =IF(AND($A11<>"",$B11<>"",$R11='تقرير مايو'!$C$4,$P11='تقرير مايو'!$C$6),COUNT(AE$4:AE10)+1,"")
K12: =IF($B12="","",IFERROR(INDEX(الموظفات!$A$5:$A$304,MATCH($B12,الموظفات!$B$5:$B$304,0))&"","")) | L12: =IF($B12="","",IFERROR(INDEX(الموظفات!$C$5:$C$304,MATCH($B12,الموظفات!$B$5:$B$304,0))&"","")) | M12: =IF($B12="","",IFERROR(INDEX(الموظفات!$D$5:$D$304,MATCH($B12,الموظفات!$B$5:$B$304,0))&"","")) | N12: =IF($B12="","",IFERROR(INDEX(الموظفات!$E$5:$E$304,MATCH($B12,الموظفات!$B$5:$B$304,0))&"","")) | O12: =IF(C12="","",IFERROR(INDEX(الإعدادات!$D$7:$D$35,MATCH(C12,الإعدادات!$A$7:$A$35,0))&"","")) | P12: =IF(A12="","",INDEX(الإعدادات!$H$7:$H$18,MONTH(A12))) | Q12: =IF(A12="","",INDEX(الإعدادات!$I$7:$I$18,MONTH(A12))) | R12: =IF(A12="","",IF(MONTH(A12)>=8,YEAR(A12)&"-"&(YEAR(A12)+1),(YEAR(A12)-1)&"-"&YEAR(A12))) | S12: =IF(OR(A12="",B12=""),0,IF(AND(R12=التقارير!$C$4,OR(التقارير!$C$5="سنوي",AND(التقارير!$C$5="شهري",P12=التقارير!$C$6),AND(التقارير!$C$5="فصلي",Q12=التقارير!$C$7))),1,0)) | T12: =IF(S12=1,COUNTIF($S$5:S12,1),"") | U12: =IF(AND($A12<>"",$B12<>"",$R12='تقرير الفصل الأول'!$C$4,$Q12='تقرير الفصل الأول'!$C$7),COUNT(U$4:U11)+1,"") | V12: =IF(AND($A12<>"",$B12<>"",$R12='تقرير الفصل الثاني'!$C$4,$Q12='تقرير الفصل الثاني'!$C$7),COUNT(V$4:V11)+1,"") | W12: =IF(AND($A12<>"",$B12<>"",$R12='تقرير سبتمبر'!$C$4,$P12='تقرير سبتمبر'!$C$6),COUNT(W$4:W11)+1,"") | X12: =IF(AND($A12<>"",$B12<>"",$R12='تقرير أكتوبر'!$C$4,$P12='تقرير أكتوبر'!$C$6),COUNT(X$4:X11)+1,"") | Y12: =IF(AND($A12<>"",$B12<>"",$R12='تقرير نوفمبر'!$C$4,$P12='تقرير نوفمبر'!$C$6),COUNT(Y$4:Y11)+1,"") | Z12: =IF(AND($A12<>"",$B12<>"",$R12='تقرير ديسمبر'!$C$4,$P12='تقرير ديسمبر'!$C$6),COUNT(Z$4:Z11)+1,"") | AA12: =IF(AND($A12<>"",$B12<>"",$R12='تقرير يناير'!$C$4,$P12='تقرير يناير'!$C$6),COUNT(AA$4:AA11)+1,"") | AB12: =IF(AND($A12<>"",$B12<>"",$R12='تقرير فبراير'!$C$4,$P12='تقرير فبراير'!$C$6),COUNT(AB$4:AB11)+1,"") | AC12: =IF(AND($A12<>"",$B12<>"",$R12='تقرير مارس'!$C$4,$P12='تقرير مارس'!$C$6),COUNT(AC$4:AC11)+1,"") | AD12: =IF(AND($A12<>"",$B12<>"",$R12='تقرير أبريل'!$C$4,$P12='تقرير أبريل'!$C$6),COUNT(AD$4:AD11)+1,"") | AE12: =IF(AND($A12<>"",$B12<>"",$R12='تقرير مايو'!$C$4,$P12='تقرير مايو'!$C$6),COUNT(AE$4:AE11)+1,"")
K13: =IF($B13="","",IFERROR(INDEX(الموظفات!$A$5:$A$304,MATCH($B13,الموظفات!$B$5:$B$304,0))&"","")) | L13: =IF($B13="","",IFERROR(INDEX(الموظفات!$C$5:$C$304,MATCH($B13,الموظفات!$B$5:$B$304,0))&"","")) | M13: =IF($B13="","",IFERROR(INDEX(الموظفات!$D$5:$D$304,MATCH($B13,الموظفات!$B$5:$B$304,0))&"","")) | N13: =IF($B13="","",IFERROR(INDEX(الموظفات!$E$5:$E$304,MATCH($B13,الموظفات!$B$5:$B$304,0))&"","")) | O13: =IF(C13="","",IFERROR(INDEX(الإعدادات!$D$7:$D$35,MATCH(C13,الإعدادات!$A$7:$A$35,0))&"","")) | P13: =IF(A13="","",INDEX(الإعدادات!$H$7:$H$18,MONTH(A13))) | Q13: =IF(A13="","",INDEX(الإعدادات!$I$7:$I$18,MONTH(A13))) | R13: =IF(A13="","",IF(MONTH(A13)>=8,YEAR(A13)&"-"&(YEAR(A13)+1),(YEAR(A13)-1)&"-"&YEAR(A13))) | S13: =IF(OR(A13="",B13=""),0,IF(AND(R13=التقارير!$C$4,OR(التقارير!$C$5="سنوي",AND(التقارير!$C$5="شهري",P13=التقارير!$C$6),AND(التقارير!$C$5="فصلي",Q13=التقارير!$C$7))),1,0)) | T13: =IF(S13=1,COUNTIF($S$5:S13,1),"") | U13: =IF(AND($A13<>"",$B13<>"",$R13='تقرير الفصل الأول'!$C$4,$Q13='تقرير الفصل الأول'!$C$7),COUNT(U$4:U12)+1,"") | V13: =IF(AND($A13<>"",$B13<>"",$R13='تقرير الفصل الثاني'!$C$4,$Q13='تقرير الفصل الثاني'!$C$7),COUNT(V$4:V12)+1,"") | W13: =IF(AND($A13<>"",$B13<>"",$R13='تقرير سبتمبر'!$C$4,$P13='تقرير سبتمبر'!$C$6),COUNT(W$4:W12)+1,"") | X13: =IF(AND($A13<>"",$B13<>"",$R13='تقرير أكتوبر'!$C$4,$P13='تقرير أكتوبر'!$C$6),COUNT(X$4:X12)+1,"") | Y13: =IF(AND($A13<>"",$B13<>"",$R13='تقرير نوفمبر'!$C$4,$P13='تقرير نوفمبر'!$C$6),COUNT(Y$4:Y12)+1,"") | Z13: =IF(AND($A13<>"",$B13<>"",$R13='تقرير ديسمبر'!$C$4,$P13='تقرير ديسمبر'!$C$6),COUNT(Z$4:Z12)+1,"") | AA13: =IF(AND($A13<>"",$B13<>"",$R13='تقرير يناير'!$C$4,$P13='تقرير يناير'!$C$6),COUNT(AA$4:AA12)+1,"") | AB13: =IF(AND($A13<>"",$B13<>"",$R13='تقرير فبراير'!$C$4,$P13='تقرير فبراير'!$C$6),COUNT(AB$4:AB12)+1,"") | AC13: =IF(AND($A13<>"",$B13<>"",$R13='تقرير مارس'!$C$4,$P13='تقرير مارس'!$C$6),COUNT(AC$4:AC12)+1,"") | AD13: =IF(AND($A13<>"",$B13<>"",$R13='تقرير أبريل'!$C$4,$P13='تقرير أبريل'!$C$6),COUNT(AD$4:AD12)+1,"") | AE13: =IF(AND($A13<>"",$B13<>"",$R13='تقرير مايو'!$C$4,$P13='تقرير مايو'!$C$6),COUNT(AE$4:AE12)+1,"")
K14: =IF($B14="","",IFERROR(INDEX(الموظفات!$A$5:$A$304,MATCH($B14,الموظفات!$B$5:$B$304,0))&"","")) | L14: =IF($B14="","",IFERROR(INDEX(الموظفات!$C$5:$C$304,MATCH($B14,الموظفات!$B$5:$B$304,0))&"","")) | M14: =IF($B14="","",IFERROR(INDEX(الموظفات!$D$5:$D$304,MATCH($B14,الموظفات!$B$5:$B$304,0))&"","")) | N14: =IF($B14="","",IFERROR(INDEX(الموظفات!$E$5:$E$304,MATCH($B14,الموظفات!$B$5:$B$304,0))&"","")) | O14: =IF(C14="","",IFERROR(INDEX(الإعدادات!$D$7:$D$35,MATCH(C14,الإعدادات!$A$7:$A$35,0))&"","")) | P14: =IF(A14="","",INDEX(الإعدادات!$H$7:$H$18,MONTH(A14))) | Q14: =IF(A14="","",INDEX(الإعدادات!$I$7:$I$18,MONTH(A14))) | R14: =IF(A14="","",IF(MONTH(A14)>=8,YEAR(A14)&"-"&(YEAR(A14)+1),(YEAR(A14)-1)&"-"&YEAR(A14))) | S14: =IF(OR(A14="",B14=""),0,IF(AND(R14=التقارير!$C$4,OR(التقارير!$C$5="سنوي",AND(التقارير!$C$5="شهري",P14=التقارير!$C$6),AND(التقارير!$C$5="فصلي",Q14=التقارير!$C$7))),1,0)) | T14: =IF(S14=1,COUNTIF($S$5:S14,1),"") | U14: =IF(AND($A14<>"",$B14<>"",$R14='تقرير الفصل الأول'!$C$4,$Q14='تقرير الفصل الأول'!$C$7),COUNT(U$4:U13)+1,"") | V14: =IF(AND($A14<>"",$B14<>"",$R14='تقرير الفصل الثاني'!$C$4,$Q14='تقرير الفصل الثاني'!$C$7),COUNT(V$4:V13)+1,"") | W14: =IF(AND($A14<>"",$B14<>"",$R14='تقرير سبتمبر'!$C$4,$P14='تقرير سبتمبر'!$C$6),COUNT(W$4:W13)+1,"") | X14: =IF(AND($A14<>"",$B14<>"",$R14='تقرير أكتوبر'!$C$4,$P14='تقرير أكتوبر'!$C$6),COUNT(X$4:X13)+1,"") | Y14: =IF(AND($A14<>"",$B14<>"",$R14='تقرير نوفمبر'!$C$4,$P14='تقرير نوفمبر'!$C$6),COUNT(Y$4:Y13)+1,"") | Z14: =IF(AND($A14<>"",$B14<>"",$R14='تقرير ديسمبر'!$C$4,$P14='تقرير ديسمبر'!$C$6),COUNT(Z$4:Z13)+1,"") | AA14: =IF(AND($A14<>"",$B14<>"",$R14='تقرير يناير'!$C$4,$P14='تقرير يناير'!$C$6),COUNT(AA$4:AA13)+1,"") | AB14: =IF(AND($A14<>"",$B14<>"",$R14='تقرير فبراير'!$C$4,$P14='تقرير فبراير'!$C$6),COUNT(AB$4:AB13)+1,"") | AC14: =IF(AND($A14<>"",$B14<>"",$R14='تقرير مارس'!$C$4,$P14='تقرير مارس'!$C$6),COUNT(AC$4:AC13)+1,"") | AD14: =IF(AND($A14<>"",$B14<>"",$R14='تقرير أبريل'!$C$4,$P14='تقرير أبريل'!$C$6),COUNT(AD$4:AD13)+1,"") | AE14: =IF(AND($A14<>"",$B14<>"",$R14='تقرير مايو'!$C$4,$P14='تقرير مايو'!$C$6),COUNT(AE$4:AE13)+1,"")
K15: =IF($B15="","",IFERROR(INDEX(الموظفات!$A$5:$A$304,MATCH($B15,الموظفات!$B$5:$B$304,0))&"","")) | L15: =IF($B15="","",IFERROR(INDEX(الموظفات!$C$5:$C$304,MATCH($B15,الموظفات!$B$5:$B$304,0))&"","")) | M15: =IF($B15="","",IFERROR(INDEX(الموظفات!$D$5:$D$304,MATCH($B15,الموظفات!$B$5:$B$304,0))&"","")) | N15: =IF($B15="","",IFERROR(INDEX(الموظفات!$E$5:$E$304,MATCH($B15,الموظفات!$B$5:$B$304,0))&"","")) | O15: =IF(C15="","",IFERROR(INDEX(الإعدادات!$D$7:$D$35,MATCH(C15,الإعدادات!$A$7:$A$35,0))&"","")) | P15: =IF(A15="","",INDEX(الإعدادات!$H$7:$H$18,MONTH(A15))) | Q15: =IF(A15="","",INDEX(الإعدادات!$I$7:$I$18,MONTH(A15))) | R15: =IF(A15="","",IF(MONTH(A15)>=8,YEAR(A15)&"-"&(YEAR(A15)+1),(YEAR(A15)-1)&"-"&YEAR(A15))) | S15: =IF(OR(A15="",B15=""),0,IF(AND(R15=التقارير!$C$4,OR(التقارير!$C$5="سنوي",AND(التقارير!$C$5="شهري",P15=التقارير!$C$6),AND(التقارير!$C$5="فصلي",Q15=التقارير!$C$7))),1,0)) | T15: =IF(S15=1,COUNTIF($S$5:S15,1),"") | U15: =IF(AND($A15<>"",$B15<>"",$R15='تقرير الفصل الأول'!$C$4,$Q15='تقرير الفصل الأول'!$C$7),COUNT(U$4:U14)+1,"") | V15: =IF(AND($A15<>"",$B15<>"",$R15='تقرير الفصل الثاني'!$C$4,$Q15='تقرير الفصل الثاني'!$C$7),COUNT(V$4:V14)+1,"") | W15: =IF(AND($A15<>"",$B15<>"",$R15='تقرير سبتمبر'!$C$4,$P15='تقرير سبتمبر'!$C$6),COUNT(W$4:W14)+1,"") | X15: =IF(AND($A15<>"",$B15<>"",$R15='تقرير أكتوبر'!$C$4,$P15='تقرير أكتوبر'!$C$6),COUNT(X$4:X14)+1,"") | Y15: =IF(AND($A15<>"",$B15<>"",$R15='تقرير نوفمبر'!$C$4,$P15='تقرير نوفمبر'!$C$6),COUNT(Y$4:Y14)+1,"") | Z15: =IF(AND($A15<>"",$B15<>"",$R15='تقرير ديسمبر'!$C$4,$P15='تقرير ديسمبر'!$C$6),COUNT(Z$4:Z14)+1,"") | AA15: =IF(AND($A15<>"",$B15<>"",$R15='تقرير يناير'!$C$4,$P15='تقرير يناير'!$C$6),COUNT(AA$4:AA14)+1,"") | AB15: =IF(AND($A15<>"",$B15<>"",$R15='تقرير فبراير'!$C$4,$P15='تقرير فبراير'!$C$6),COUNT(AB$4:AB14)+1,"") | AC15: =IF(AND($A15<>"",$B15<>"",$R15='تقرير مارس'!$C$4,$P15='تقرير مارس'!$C$6),COUNT(AC$4:AC14)+1,"") | AD15: =IF(AND($A15<>"",$B15<>"",$R15='تقرير أبريل'!$C$4,$P15='تقرير أبريل'!$C$6),COUNT(AD$4:AD14)+1,"") | AE15: =IF(AND($A15<>"",$B15<>"",$R15='تقرير مايو'!$C$4,$P15='تقرير مايو'!$C$6),COUNT(AE$4:AE14)+1,"")
K16: =IF($B16="","",IFERROR(INDEX(الموظفات!$A$5:$A$304,MATCH($B16,الموظفات!$B$5:$B$304,0))&"","")) | L16: =IF($B16="","",IFERROR(INDEX(الموظفات!$C$5:$C$304,MATCH($B16,الموظفات!$B$5:$B$304,0))&"","")) | M16: =IF($B16="","",IFERROR(INDEX(الموظفات!$D$5:$D$304,MATCH($B16,الموظفات!$B$5:$B$304,0))&"","")) | N16: =IF($B16="","",IFERROR(INDEX(الموظفات!$E$5:$E$304,MATCH($B16,الموظفات!$B$5:$B$304,0))&"","")) | O16: =IF(C16="","",IFERROR(INDEX(الإعدادات!$D$7:$D$35,MATCH(C16,الإعدادات!$A$7:$A$35,0))&"","")) | P16: =IF(A16="","",INDEX(الإعدادات!$H$7:$H$18,MONTH(A16))) | Q16: =IF(A16="","",INDEX(الإعدادات!$I$7:$I$18,MONTH(A16))) | R16: =IF(A16="","",IF(MONTH(A16)>=8,YEAR(A16)&"-"&(YEAR(A16)+1),(YEAR(A16)-1)&"-"&YEAR(A16))) | S16: =IF(OR(A16="",B16=""),0,IF(AND(R16=التقارير!$C$4,OR(التقارير!$C$5="سنوي",AND(التقارير!$C$5="شهري",P16=التقارير!$C$6),AND(التقارير!$C$5="فصلي",Q16=التقارير!$C$7))),1,0)) | T16: =IF(S16=1,COUNTIF($S$5:S16,1),"") | U16: =IF(AND($A16<>"",$B16<>"",$R16='تقرير الفصل الأول'!$C$4,$Q16='تقرير الفصل الأول'!$C$7),COUNT(U$4:U15)+1,"") | V16: =IF(AND($A16<>"",$B16<>"",$R16='تقرير الفصل الثاني'!$C$4,$Q16='تقرير الفصل الثاني'!$C$7),COUNT(V$4:V15)+1,"") | W16: =IF(AND($A16<>"",$B16<>"",$R16='تقرير سبتمبر'!$C$4,$P16='تقرير سبتمبر'!$C$6),COUNT(W$4:W15)+1,"") | X16: =IF(AND($A16<>"",$B16<>"",$R16='تقرير أكتوبر'!$C$4,$P16='تقرير أكتوبر'!$C$6),COUNT(X$4:X15)+1,"") | Y16: =IF(AND($A16<>"",$B16<>"",$R16='تقرير نوفمبر'!$C$4,$P16='تقرير نوفمبر'!$C$6),COUNT(Y$4:Y15)+1,"") | Z16: =IF(AND($A16<>"",$B16<>"",$R16='تقرير ديسمبر'!$C$4,$P16='تقرير ديسمبر'!$C$6),COUNT(Z$4:Z15)+1,"") | AA16: =IF(AND($A16<>"",$B16<>"",$R16='تقرير يناير'!$C$4,$P16='تقرير يناير'!$C$6),COUNT(AA$4:AA15)+1,"") | AB16: =IF(AND($A16<>"",$B16<>"",$R16='تقرير فبراير'!$C$4,$P16='تقرير فبراير'!$C$6),COUNT(AB$4:AB15)+1,"") | AC16: =IF(AND($A16<>"",$B16<>"",$R16='تقرير مارس'!$C$4,$P16='تقرير مارس'!$C$6),COUNT(AC$4:AC15)+1,"") | AD16: =IF(AND($A16<>"",$B16<>"",$R16='تقرير أبريل'!$C$4,$P16='تقرير أبريل'!$C$6),COUNT(AD$4:AD15)+1,"") | AE16: =IF(AND($A16<>"",$B16<>"",$R16='تقرير مايو'!$C$4,$P16='تقرير مايو'!$C$6),COUNT(AE$4:AE15)+1,"")
... K2004: =IF($B2004="","",IFERROR(INDEX(الموظفات!$A$5:$A$304,MATCH($B2004,الموظفات!$B$5:$B$304,0))&"","")) | L2004: =IF($B2004="","",IFERROR(INDEX(الموظفات!$C$5:$C$304,MATCH($B2004,الموظفات!$B$5:$B$304,0))&"","")) | M2004: =IF($B2004="","",IFERROR(INDEX(الموظفات!$D$5:$D$304,MATCH($B2004,الموظفات!$B$5:$B$304,0))&"","")) | N2004: =IF($B2004="","",IFERROR(INDEX(الموظفات!$E$5:$E$304,MATCH($B2004,الموظفات!$B$5:$B$304,0))&"","")) | O2004: =IF(C2004="","",IFERROR(INDEX(الإعدادات!$D$7:$D$35,MATCH(C2004,الإعدادات!$A$7:$A$35,0))&"","")) | P2004: =IF(A2004="","",INDEX(الإعدادات!$H$7:$H$18,MONTH(A2004))) | Q2004: =IF(A2004="","",INDEX(الإعدادات!$I$7:$I$18,MONTH(A2004))) | R2004: =IF(A2004="","",IF(MONTH(A2004)>=8,YEAR(A2004)&"-"&(YEAR(A2004)+1),(YEAR(A2004)-1)&"-"&YEAR(A2004))) | S2004: =IF(OR(A2004="",B2004=""),0,IF(AND(R2004=التقارير!$C$4,OR(التقارير!$C$5="سنوي",AND(التقارير!$C$5="شهري",P2004=التقارير!$C$6),AND(التقارير!$C$5="فصلي",Q2004=التقارير!$C$7))),1,0)) | T2004: =IF(S2004=1,COUNTIF($S$5:S2004,1),"") | U2004: =IF(AND($A2004<>"",$B2004<>"",$R2004='تقرير الفصل الأول'!$C$4,$Q2004='تقرير الفصل الأول'!$C$7),COUNT(U$4:U2003)+1,"") | V2004: =IF(AND($A2004<>"",$B2004<>"",$R2004='تقرير الفصل الثاني'!$C$4,$Q2004='تقرير الفصل الثاني'!$C$7),COUNT(V$4:V2003)+1,"") | W2004: =IF(AND($A2004<>"",$B2004<>"",$R2004='تقرير سبتمبر'!$C$4,$P2004='تقرير سبتمبر'!$C$6),COUNT(W$4:W2003)+1,"") | X2004: =IF(AND($A2004<>"",$B2004<>"",$R2004='تقرير أكتوبر'!$C$4,$P2004='تقرير أكتوبر'!$C$6),COUNT(X$4:X2003)+1,"") | Y2004: =IF(AND($A2004<>"",$B2004<>"",$R2004='تقرير نوفمبر'!$C$4,$P2004='تقرير نوفمبر'!$C$6),COUNT(Y$4:Y2003)+1,"") | Z2004: =IF(AND($A2004<>"",$B2004<>"",$R2004='تقرير ديسمبر'!$C$4,$P2004='تقرير ديسمبر'!$C$6),COUNT(Z$4:Z2003)+1,"") | AA2004: =IF(AND($A2004<>"",$B2004<>"",$R2004='تقرير يناير'!$C$4,$P2004='تقرير يناير'!$C$6),COUNT(AA$4:AA2003)+1,"") | AB2004: =IF(AND($A2004<>"",$B2004<>"",$R2004='تقرير فبراير'!$C$4,$P2004='تقرير فبراير'!$C$6),COUNT(AB$4:AB2003)+1,"") | AC2004: =IF(AND($A2004<>"",$B2004<>"",$R2004='تقرير مارس'!$C$4,$P2004='تقرير مارس'!$C$6),COUNT(AC$4:AC2003)+1,"") | AD2004: =IF(AND($A2004<>"",$B2004<>"",$R2004='تقرير أبريل'!$C$4,$P2004='تقرير أبريل'!$C$6),COUNT(AD$4:AD2003)+1,"") | AE2004: =IF(AND($A2004<>"",$B2004<>"",$R2004='تقرير مايو'!$C$4,$P2004='تقرير مايو'!$C$6),COUNT(AE$4:AE2003)+1,"")

Sheet الموظفات
A1: بيانات الموظفات
A2: منقولة من كشف موظفات المدرسة. أضيفي الرقم الوظيفي في العمود A. الأعمدة الرمادية (من H) تُحسب من السجل للسنة الدراسية الحالية.
A4: الرقم الوظيفي | B4: اسم الموظفة | C4: المسمى الوظيفي | D4: القسم | E4: الفئة | F4: البريد الإلكتروني | G4: الحالة | H4: إجمالي التكريمات (السنة) | I4: معايير ذهبية - الفصل الأول | J4: معايير ذهبية - الفصل الثاني | K4: إجمالي المعايير الذهبية (السنة) | L4: كوبون أمري تدللي | N4: مُكرَّمة: التقارير | O4: مُكرَّمة: تقرير الفصل الأول | P4: مُكرَّمة: تقرير الفصل الثاني | Q4: مُكرَّمة: تقرير سبتمبر | R4: مُكرَّمة: تقرير أكتوبر | S4: مُكرَّمة: تقرير نوفمبر | T4: مُكرَّمة: تقرير ديسمبر | U4: مُكرَّمة: تقرير يناير | V4: مُكرَّمة: تقرير فبراير | W4: مُكرَّمة: تقرير مارس | X4: مُكرَّمة: تقرير أبريل | Y4: مُكرَّمة: تقرير مايو
H5: =IF(B5="","",COUNTIFS('سجل التحفيز'!$B$5:$B$2004,B5,'سجل التحفيز'!$R$5:$R$2004,الإعدادات!$B$4)) | I5: =IF(B5="","",COUNTIFS('سجل التحفيز'!$B$5:$B$2004,B5,'سجل التحفيز'!$R$5:$R$2004,الإعدادات!$B$4,'سجل التحفيز'!$Q$5:$Q$2004,"الفصل الأول",'سجل التحفيز'!$D$5:$D$2004,"ذهبي")) | J5: =IF(B5="","",COUNTIFS('سجل التحفيز'!$B$5:$B$2004,B5,'سجل التحفيز'!$R$5:$R$2004,الإعدادات!$B$4,'سجل التحفيز'!$Q$5:$Q$2004,"الفصل الثاني",'سجل التحفيز'!$D$5:$D$2004,"ذهبي")) | K5: =IF(B5="","",COUNTIFS('سجل التحفيز'!$B$5:$B$2004,B5,'سجل التحفيز'!$R$5:$R$2004,الإعدادات!$B$4,'سجل التحفيز'!$D$5:$D$2004,"ذهبي")) | L5: =IF(B5="","",IF(G5="محرومة","محرومة - مخالفة",IF(K5>=5,"مستحقة ★","متبقي "&(5-K5)&" معايير"))) | N5: =IF(B5="","",IF(COUNTIFS('سجل التحفيز'!$T$5:$T$2004,">0",'سجل التحفيز'!$B$5:$B$2004,B5)>0,COUNT(N$4:N4)+1,"")) | O5: =IF(B5="","",IF(COUNTIFS('سجل التحفيز'!$U$5:$U$2004,">0",'سجل التحفيز'!$B$5:$B$2004,B5)>0,COUNT(O$4:O4)+1,"")) | P5: =IF(B5="","",IF(COUNTIFS('سجل التحفيز'!$V$5:$V$2004,">0",'سجل التحفيز'!$B$5:$B$2004,B5)>0,COUNT(P$4:P4)+1,"")) | Q5: =IF(B5="","",IF(COUNTIFS('سجل التحفيز'!$W$5:$W$2004,">0",'سجل التحفيز'!$B$5:$B$2004,B5)>0,COUNT(Q$4:Q4)+1,"")) | R5: =IF(B5="","",IF(COUNTIFS('سجل التحفيز'!$X$5:$X$2004,">0",'سجل التحفيز'!$B$5:$B$2004,B5)>0,COUNT(R$4:R4)+1,"")) | S5: =IF(B5="","",IF(COUNTIFS('سجل التحفيز'!$Y$5:$Y$2004,">0",'سجل التحفيز'!$B$5:$B$2004,B5)>0,COUNT(S$4:S4)+1,"")) | T5: =IF(B5="","",IF(COUNTIFS('سجل التحفيز'!$Z$5:$Z$2004,">0",'سجل التحفيز'!$B$5:$B$2004,B5)>0,COUNT(T$4:T4)+1,"")) | U5: =IF(B5="","",IF(COUNTIFS('سجل التحفيز'!$AA$5:$AA$2004,">0",'سجل التحفيز'!$B$5:$B$2004,B5)>0,COUNT(U$4:U4)+1,"")) | V5: =IF(B5="","",IF(COUNTIFS('سجل التحفيز'!$AB$5:$AB$2004,">0",'سجل التحفيز'!$B$5:$B$2004,B5)>0,COUNT(V$4:V4)+1,"")) | W5: =IF(B5="","",IF(COUNTIFS('سجل التحفيز'!$AC$5:$AC$2004,">0",'سجل التحفيز'!$B$5:$B$2004,B5)>0,COUNT(W$4:W4)+1,"")) | X5: =IF(B5="","",IF(COUNTIFS('سجل التحفيز'!$AD$5:$AD$2004,">0",'سجل التحفيز'!$B$5:$B$2004,B5)>0,COUNT(X$4:X4)+1,"")) | Y5: =IF(B5="","",IF(COUNTIFS('سجل التحفيز'!$AE$5:$AE$2004,">0",'سجل التحفيز'!$B$5:$B$2004,B5)>0,COUNT(Y$4:Y4)+1,""))
H6: =IF(B6="","",COUNTIFS('سجل التحفيز'!$B$5:$B$2004,B6,'سجل التحفيز'!$R$5:$R$2004,الإعدادات!$B$4)) | I6: =IF(B6="","",COUNTIFS('سجل التحفيز'!$B$5:$B$2004,B6,'سجل التحفيز'!$R$5:$R$2004,الإعدادات!$B$4,'سجل التحفيز'!$Q$5:$Q$2004,"الفصل الأول",'سجل التحفيز'!$D$5:$D$2004,"ذهبي")) | J6: =IF(B6="","",COUNTIFS('سجل التحفيز'!$B$5:$B$2004,B6,'سجل التحفيز'!$R$5:$R$2004,الإعدادات!$B$4,'سجل التحفيز'!$Q$5:$Q$2004,"الفصل الثاني",'سجل التحفيز'!$D$5:$D$2004,"ذهبي")) | K6: =IF(B6="","",COUNTIFS('سجل التحفيز'!$B$5:$B$2004,B6,'سجل التحفيز'!$R$5:$R$2004,الإعدادات!$B$4,'سجل التحفيز'!$D$5:$D$2004,"ذهبي")) | L6: =IF(B6="","",IF(G6="محرومة","محرومة - مخالفة",IF(K6>=5,"مستحقة ★","متبقي "&(5-K6)&" معايير"))) | N6: =IF(B6="","",IF(COUNTIFS('سجل التحفيز'!$T$5:$T$2004,">0",'سجل التحفيز'!$B$5:$B$2004,B6)>0,COUNT(N$4:N5)+1,"")) | O6: =IF(B6="","",IF(COUNTIFS('سجل التحفيز'!$U$5:$U$2004,">0",'سجل التحفيز'!$B$5:$B$2004,B6)>0,COUNT(O$4:O5)+1,"")) | P6: =IF(B6="","",IF(COUNTIFS('سجل التحفيز'!$V$5:$V$2004,">0",'سجل التحفيز'!$B$5:$B$2004,B6)>0,COUNT(P$4:P5)+1,"")) | Q6: =IF(B6="","",IF(COUNTIFS('سجل التحفيز'!$W$5:$W$2004,">0",'سجل التحفيز'!$B$5:$B$2004,B6)>0,COUNT(Q$4:Q5)+1,"")) | R6: =IF(B6="","",IF(COUNTIFS('سجل التحفيز'!$X$5:$X$2004,">0",'سجل التحفيز'!$B$5:$B$2004,B6)>0,COUNT(R$4:R5)+1,"")) | S6: =IF(B6="","",IF(COUNTIFS('سجل التحفيز'!$Y$5:$Y$2004,">0",'سجل التحفيز'!$B$5:$B$2004,B6)>0,COUNT(S$4:S5)+1,"")) | T6: =IF(B6="","",IF(COUNTIFS('سجل التحفيز'!$Z$5:$Z$2004,">0",'سجل التحفيز'!$B$5:$B$2004,B6)>0,COUNT(T$4:T5)+1,"")) | U6: =IF(B6="","",IF(COUNTIFS('سجل التحفيز'!$AA$5:$AA$2004,">0",'سجل التحفيز'!$B$5:$B$2004,B6)>0,COUNT(U$4:U5)+1,"")) | V6: =IF(B6="","",IF(COUNTIFS('سجل التحفيز'!$AB$5:$AB$2004,">0",'سجل التحفيز'!$B$5:$B$2004,B6)>0,COUNT(V$4:V5)+1,"")) | W6: =IF(B6="","",IF(COUNTIFS('سجل التحفيز'!$AC$5:$AC$2004,">0",'سجل التحفيز'!$B$5:$B$2004,B6)>0,COUNT(W$4:W5)+1,"")) | X6: =IF(B6="","",IF(COUNTIFS('سجل التحفيز'!$AD$5:$AD$2004,">0",'سجل التحفيز'!$B$5:$B$2004,B6)>0,COUNT(X$4:X5)+1,"")) | Y6: =IF(B6="","",IF(COUNTIFS('سجل التحفيز'!$AE$5:$AE$2004,">0",'سجل التحفيز'!$B$5:$B$2004,B6)>0,COUNT(Y$4:Y5)+1,""))
H7: =IF(B7="","",COUNTIFS('سجل التحفيز'!$B$5:$B$2004,B7,'سجل التحفيز'!$R$5:$R$2004,الإعدادات!$B$4)) | I7: =IF(B7="","",COUNTIFS('سجل التحفيز'!$B$5:$B$2004,B7,'سجل التحفيز'!$R$5:$R$2004,الإعدادات!$B$4,'سجل التحفيز'!$Q$5:$Q$2004,"الفصل الأول",'سجل التحفيز'!$D$5:$D$2004,"ذهبي")) | J7: =IF(B7="","",COUNTIFS('سجل التحفيز'!$B$5:$B$2004,B7,'سجل التحفيز'!$R$5:$R$2004,الإعدادات!$B$4,'سجل التحفيز'!$Q$5:$Q$2004,"الفصل الثاني",'سجل التحفيز'!$D$5:$D$2004,"ذهبي")) | K7: =IF(B7="","",COUNTIFS('سجل التحفيز'!$B$5:$B$2004,B7,'سجل التحفيز'!$R$5:$R$2004,الإعدادات!$B$4,'سجل التحفيز'!$D$5:$D$2004,"ذهبي")) | L7: =IF(B7="","",IF(G7="محرومة","محرومة - مخالفة",IF(K7>=5,"مستحقة ★","متبقي "&(5-K7)&" معايير"))) | N7: =IF(B7="","",IF(COUNTIFS('سجل التحفيز'!$T$5:$T$2004,">0",'سجل التحفيز'!$B$5:$B$2004,B7)>0,COUNT(N$4:N6)+1,"")) | O7: =IF(B7="","",IF(COUNTIFS('سجل التحفيز'!$U$5:$U$2004,">0",'سجل التحفيز'!$B$5:$B$2004,B7)>0,COUNT(O$4:O6)+1,"")) | P7: =IF(B7="","",IF(COUNTIFS('سجل التحفيز'!$V$5:$V$2004,">0",'سجل التحفيز'!$B$5:$B$2004,B7)>0,COUNT(P$4:P6)+1,"")) | Q7: =IF(B7="","",IF(COUNTIFS('سجل التحفيز'!$W$5:$W$2004,">0",'سجل التحفيز'!$B$5:$B$2004,B7)>0,COUNT(Q$4:Q6)+1,"")) | R7: =IF(B7="","",IF(COUNTIFS('سجل التحفيز'!$X$5:$X$2004,">0",'سجل التحفيز'!$B$5:$B$2004,B7)>0,COUNT(R$4:R6)+1,"")) | S7: =IF(B7="","",IF(COUNTIFS('سجل التحفيز'!$Y$5:$Y$2004,">0",'سجل التحفيز'!$B$5:$B$2004,B7)>0,COUNT(S$4:S6)+1,"")) | T7: =IF(B7="","",IF(COUNTIFS('سجل التحفيز'!$Z$5:$Z$2004,">0",'سجل التحفيز'!$B$5:$B$2004,B7)>0,COUNT(T$4:T6)+1,"")) | U7: =IF(B7="","",IF(COUNTIFS('سجل التحفيز'!$AA$5:$AA$2004,">0",'سجل التحفيز'!$B$5:$B$2004,B7)>0,COUNT(U$4:U6)+1,"")) | V7: =IF(B7="","",IF(COUNTIFS('سجل التحفيز'!$AB$5:$AB$2004,">0",'سجل التحفيز'!$B$5:$B$2004,B7)>0,COUNT(V$4:V6)+1,"")) | W7: =IF(B7="","",IF(COUNTIFS('سجل التحفيز'!$AC$5:$AC$2004,">0",'سجل التحفيز'!$B$5:$B$2004,B7)>0,COUNT(W$4:W6)+1,"")) | X7: =IF(B7="","",IF(COUNTIFS('سجل التحفيز'!$AD$5:$AD$2004,">0",'سجل التحفيز'!$B$5:$B$2004,B7)>0,COUNT(X$4:X6)+1,"")) | Y7: =IF(B7="","",IF(COUNTIFS('سجل التحفيز'!$AE$5:$AE$2004,">0",'سجل التحفيز'!$B$5:$B$2004,B7)>0,COUNT(Y$4:Y6)+1,""))
H8: =IF(B8="","",COUNTIFS('سجل التحفيز'!$B$5:$B$2004,B8,'سجل التحفيز'!$R$5:$R$2004,الإعدادات!$B$4)) | I8: =IF(B8="","",COUNTIFS('سجل التحفيز'!$B$5:$B$2004,B8,'سجل التحفيز'!$R$5:$R$2004,الإعدادات!$B$4,'سجل التحفيز'!$Q$5:$Q$2004,"الفصل الأول",'سجل التحفيز'!$D$5:$D$2004,"ذهبي")) | J8: =IF(B8="","",COUNTIFS('سجل التحفيز'!$B$5:$B$2004,B8,'سجل التحفيز'!$R$5:$R$2004,الإعدادات!$B$4,'سجل التحفيز'!$Q$5:$Q$2004,"الفصل الثاني",'سجل التحفيز'!$D$5:$D$2004,"ذهبي")) | K8: =IF(B8="","",COUNTIFS('سجل التحفيز'!$B$5:$B$2004,B8,'سجل التحفيز'!$R$5:$R$2004,الإعدادات!$B$4,'سجل التحفيز'!$D$5:$D$2004,"ذهبي")) | L8: =IF(B8="","",IF(G8="محرومة","محرومة - مخالفة",IF(K8>=5,"مستحقة ★","متبقي "&(5-K8)&" معايير"))) | N8: =IF(B8="","",IF(COUNTIFS('سجل التحفيز'!$T$5:$T$2004,">0",'سجل التحفيز'!$B$5:$B$2004,B8)>0,COUNT(N$4:N7)+1,"")) | O8: =IF(B8="","",IF(COUNTIFS('سجل التحفيز'!$U$5:$U$2004,">0",'سجل التحفيز'!$B$5:$B$2004,B8)>0,COUNT(O$4:O7)+1,"")) | P8: =IF(B8="","",IF(COUNTIFS('سجل التحفيز'!$V$5:$V$2004,">0",'سجل التحفيز'!$B$5:$B$2004,B8)>0,COUNT(P$4:P7)+1,"")) | Q8: =IF(B8="","",IF(COUNTIFS('سجل التحفيز'!$W$5:$W$2004,">0",'سجل التحفيز'!$B$5:$B$2004,B8)>0,COUNT(Q$4:Q7)+1,"")) | R8: =IF(B8="","",IF(COUNTIFS('سجل التحفيز'!$X$5:$X$2004,">0",'سجل التحفيز'!$B$5:$B$2004,B8)>0,COUNT(R$4:R7)+1,"")) | S8: =IF(B8="","",IF(COUNTIFS('سجل التحفيز'!$Y$5:$Y$2004,">0",'سجل التحفيز'!$B$5:$B$2004,B8)>0,COUNT(S$4:S7)+1,"")) | T8: =IF(B8="","",IF(COUNTIFS('سجل التحفيز'!$Z$5:$Z$2004,">0",'سجل التحفيز'!$B$5:$B$2004,B8)>0,COUNT(T$4:T7)+1,"")) | U8: =IF(B8="","",IF(COUNTIFS('سجل التحفيز'!$AA$5:$AA$2004,">0",'سجل التحفيز'!$B$5:$B$2004,B8)>0,COUNT(U$4:U7)+1,"")) | V8: =IF(B8="","",IF(COUNTIFS('سجل التحفيز'!$AB$5:$AB$2004,">0",'سجل التحفيز'!$B$5:$B$2004,B8)>0,COUNT(V$4:V7)+1,"")) | W8: =IF(B8="","",IF(COUNTIFS('سجل التحفيز'!$AC$5:$AC$2004,">0",'سجل التحفيز'!$B$5:$B$2004,B8)>0,COUNT(W$4:W7)+1,"")) | X8: =IF(B8="","",IF(COUNTIFS('سجل التحفيز'!$AD$5:$AD$2004,">0",'سجل التحفيز'!$B$5:$B$2004,B8)>0,COUNT(X$4:X7)+1,"")) | Y8: =IF(B8="","",IF(COUNTIFS('سجل التحفيز'!$AE$5:$AE$2004,">0",'سجل التحفيز'!$B$5:$B$2004,B8)>0,COUNT(Y$4:Y7)+1,""))
H9: =IF(B9="","",COUNTIFS('سجل التحفيز'!$B$5:$B$2004,B9,'سجل التحفيز'!$R$5:$R$2004,الإعدادات!$B$4)) | I9: =IF(B9="","",COUNTIFS('سجل التحفيز'!$B$5:$B$2004,B9,'سجل التحفيز'!$R$5:$R$2004,الإعدادات!$B$4,'سجل التحفيز'!$Q$5:$Q$2004,"الفصل الأول",'سجل التحفيز'!$D$5:$D$2004,"ذهبي")) | J9: =IF(B9="","",COUNTIFS('سجل التحفيز'!$B$5:$B$2004,B9,'سجل التحفيز'!$R$5:$R$2004,الإعدادات!$B$4,'سجل التحفيز'!$Q$5:$Q$2004,"الفصل الثاني",'سجل التحفيز'!$D$5:$D$2004,"ذهبي")) | K9: =IF(B9="","",COUNTIFS('سجل التحفيز'!$B$5:$B$2004,B9,'سجل التحفيز'!$R$5:$R$2004,الإعدادات!$B$4,'سجل التحفيز'!$D$5:$D$2004,"ذهبي")) | L9: =IF(B9="","",IF(G9="محرومة","محرومة - مخالفة",IF(K9>=5,"مستحقة ★","متبقي "&(5-K9)&" معايير"))) | N9: =IF(B9="","",IF(COUNTIFS('سجل التحفيز'!$T$5:$T$2004,">0",'سجل التحفيز'!$B$5:$B$2004,B9)>0,COUNT(N$4:N8)+1,"")) | O9: =IF(B9="","",IF(COUNTIFS('سجل التحفيز'!$U$5:$U$2004,">0",'سجل التحفيز'!$B$5:$B$2004,B9)>0,COUNT(O$4:O8)+1,"")) | P9: =IF(B9="","",IF(COUNTIFS('سجل التحفيز'!$V$5:$V$2004,">0",'سجل التحفيز'!$B$5:$B$2004,B9)>0,COUNT(P$4:P8)+1,"")) | Q9: =IF(B9="","",IF(COUNTIFS('سجل التحفيز'!$W$5:$W$2004,">0",'سجل التحفيز'!$B$5:$B$2004,B9)>0,COUNT(Q$4:Q8)+1,"")) | R9: =IF(B9="","",IF(COUNTIFS('سجل التحفيز'!$X$5:$X$2004,">0",'سجل التحفيز'!$B$5:$B$2004,B9)>0,COUNT(R$4:R8)+1,"")) | S9: =IF(B9="","",IF(COUNTIFS('سجل التحفيز'!$Y$5:$Y$2004,">0",'سجل التحفيز'!$B$5:$B$2004,B9)>0,COUNT(S$4:S8)+1,"")) | T9: =IF(B9="","",IF(COUNTIFS('سجل التحفيز'!$Z$5:$Z$2004,">0",'سجل التحفيز'!$B$5:$B$2004,B9)>0,COUNT(T$4:T8)+1,"")) | U9: =IF(B9="","",IF(COUNTIFS('سجل التحفيز'!$AA$5:$AA$2004,">0",'سجل التحفيز'!$B$5:$B$2004,B9)>0,COUNT(U$4:U8)+1,"")) | V9: =IF(B9="","",IF(COUNTIFS('سجل التحفيز'!$AB$5:$AB$2004,">0",'سجل التحفيز'!$B$5:$B$2004,B9)>0,COUNT(V$4:V8)+1,"")) | W9: =IF(B9="","",IF(COUNTIFS('سجل التحفيز'!$AC$5:$AC$2004,">0",'سجل التحفيز'!$B$5:$B$2004,B9)>0,COUNT(W$4:W8)+1,"")) | X9: =IF(B9="","",IF(COUNTIFS('سجل التحفيز'!$AD$5:$AD$2004,">0",'سجل التحفيز'!$B$5:$B$2004,B9)>0,COUNT(X$4:X8)+1,"")) | Y9: =IF(B9="","",IF(COUNTIFS('سجل التحفيز'!$AE$5:$AE$2004,">0",'سجل التحفيز'!$B$5:$B$2004,B9)>0,COUNT(Y$4:Y8)+1,""))
H10: =IF(B10="","",COUNTIFS('سجل التحفيز'!$B$5:$B$2004,B10,'سجل التحفيز'!$R$5:$R$2004,الإعدادات!$B$4)) | I10: =IF(B10="","",COUNTIFS('سجل التحفيز'!$B$5:$B$2004,B10,'سجل التحفيز'!$R$5:$R$2004,الإعدادات!$B$4,'سجل التحفيز'!$Q$5:$Q$2004,"الفصل الأول",'سجل التحفيز'!$D$5:$D$2004,"ذهبي")) | J10: =IF(B10="","",COUNTIFS('سجل التحفيز'!$B$5:$B$2004,B10,'سجل التحفيز'!$R$5:$R$2004,الإعدادات!$B$4,'سجل التحفيز'!$Q$5:$Q$2004,"الفصل الثاني",'سجل التحفيز'!$D$5:$D$2004,"ذهبي")) | K10: =IF(B10="","",COUNTIFS('سجل التحفيز'!$B$5:$B$2004,B10,'سجل التحفيز'!$R$5:$R$2004,الإعدادات!$B$4,'سجل التحفيز'!$D$5:$D$2004,"ذهبي")) | L10: =IF(B10="","",IF(G10="محرومة","محرومة - مخالفة",IF(K10>=5,"مستحقة ★","متبقي "&(5-K10)&" معايير"))) | N10: =IF(B10="","",IF(COUNTIFS('سجل التحفيز'!$T$5:$T$2004,">0",'سجل التحفيز'!$B$5:$B$2004,B10)>0,COUNT(N$4:N9)+1,"")) | O10: =IF(B10="","",IF(COUNTIFS('سجل التحفيز'!$U$5:$U$2004,">0",'سجل التحفيز'!$B$5:$B$2004,B10)>0,COUNT(O$4:O9)+1,"")) | P10: =IF(B10="","",IF(COUNTIFS('سجل التحفيز'!$V$5:$V$2004,">0",'سجل التحفيز'!$B$5:$B$2004,B10)>0,COUNT(P$4:P9)+1,"")) | Q10: =IF(B10="","",IF(COUNTIFS('سجل التحفيز'!$W$5:$W$2004,">0",'سجل التحفيز'!$B$5:$B$2004,B10)>0,COUNT(Q$4:Q9)+1,"")) | R10: =IF(B10="","",IF(COUNTIFS('سجل التحفيز'!$X$5:$X$2004,">0",'سجل التحفيز'!$B$5:$B$2004,B10)>0,COUNT(R$4:R9)+1,"")) | S10: =IF(B10="","",IF(COUNTIFS('سجل التحفيز'!$Y$5:$Y$2004,">0",'سجل التحفيز'!$B$5:$B$2004,B10)>0,COUNT(S$4:S9)+1,"")) | T10: =IF(B10="","",IF(COUNTIFS('سجل التحفيز'!$Z$5:$Z$2004,">0",'سجل التحفيز'!$B$5:$B$2004,B10)>0,COUNT(T$4:T9)+1,"")) | U10: =IF(B10="","",IF(COUNTIFS('سجل التحفيز'!$AA$5:$AA$2004,">0",'سجل التحفيز'!$B$5:$B$2004,B10)>0,COUNT(U$4:U9)+1,"")) | V10: =IF(B10="","",IF(COUNTIFS('سجل التحفيز'!$AB$5:$AB$2004,">0",'سجل التحفيز'!$B$5:$B$2004,B10)>0,COUNT(V$4:V9)+1,"")) | W10: =IF(B10="","",IF(COUNTIFS('سجل التحفيز'!$AC$5:$AC$2004,">0",'سجل التحفيز'!$B$5:$B$2004,B10)>0,COUNT(W$4:W9)+1,"")) | X10: =IF(B10="","",IF(COUNTIFS('سجل التحفيز'!$AD$5:$AD$2004,">0",'سجل التحفيز'!$B$5:$B$2004,B10)>0,COUNT(X$4:X9)+1,"")) | Y10: =IF(B10="","",IF(COUNTIFS('سجل التحفيز'!$AE$5:$AE$2004,">0",'سجل التحفيز'!$B$5:$B$2004,B10)>0,COUNT(Y$4:Y9)+1,""))
H11: =IF(B11="","",COUNTIFS('سجل التحفيز'!$B$5:$B$2004,B11,'سجل التحفيز'!$R$5:$R$2004,الإعدادات!$B$4)) | I11: =IF(B11="","",COUNTIFS('سجل التحفيز'!$B$5:$B$2004,B11,'سجل التحفيز'!$R$5:$R$2004,الإعدادات!$B$4,'سجل التحفيز'!$Q$5:$Q$2004,"الفصل الأول",'سجل التحفيز'!$D$5:$D$2004,"ذهبي")) | J11: =IF(B11="","",COUNTIFS('سجل التحفيز'!$B$5:$B$2004,B11,'سجل التحفيز'!$R$5:$R$2004,الإعدادات!$B$4,'سجل التحفيز'!$Q$5:$Q$2004,"الفصل الثاني",'سجل التحفيز'!$D$5:$D$2004,"ذهبي")) | K11: =IF(B11="","",COUNTIFS('سجل التحفيز'!$B$5:$B$2004,B11,'سجل التحفيز'!$R$5:$R$2004,الإعدادات!$B$4,'سجل التحفيز'!$D$5:$D$2004,"ذهبي")) | L11: =IF(B11="","",IF(G11="محرومة","محرومة - مخالفة",IF(K11>=5,"مستحقة ★","متبقي "&(5-K11)&" معايير"))) | N11: =IF(B11="","",IF(COUNTIFS('سجل التحفيز'!$T$5:$T$2004,">0",'سجل التحفيز'!$B$5:$B$2004,B11)>0,COUNT(N$4:N10)+1,"")) | O11: =IF(B11="","",IF(COUNTIFS('سجل التحفيز'!$U$5:$U$2004,">0",'سجل التحفيز'!$B$5:$B$2004,B11)>0,COUNT(O$4:O10)+1,"")) | P11: =IF(B11="","",IF(COUNTIFS('سجل التحفيز'!$V$5:$V$2004,">0",'سجل التحفيز'!$B$5:$B$2004,B11)>0,COUNT(P$4:P10)+1,"")) | Q11: =IF(B11="","",IF(COUNTIFS('سجل التحفيز'!$W$5:$W$2004,">0",'سجل التحفيز'!$B$5:$B$2004,B11)>0,COUNT(Q$4:Q10)+1,"")) | R11: =IF(B11="","",IF(COUNTIFS('سجل التحفيز'!$X$5:$X$2004,">0",'سجل التحفيز'!$B$5:$B$2004,B11)>0,COUNT(R$4:R10)+1,"")) | S11: =IF(B11="","",IF(COUNTIFS('سجل التحفيز'!$Y$5:$Y$2004,">0",'سجل التحفيز'!$B$5:$B$2004,B11)>0,COUNT(S$4:S10)+1,"")) | T11: =IF(B11="","",IF(COUNTIFS('سجل التحفيز'!$Z$5:$Z$2004,">0",'سجل التحفيز'!$B$5:$B$2004,B11)>0,COUNT(T$4:T10)+1,"")) | U11: =IF(B11="","",IF(COUNTIFS('سجل التحفيز'!$AA$5:$AA$2004,">0",'سجل التحفيز'!$B$5:$B$2004,B11)>0,COUNT(U$4:U10)+1,"")) | V11: =IF(B11="","",IF(COUNTIFS('سجل التحفيز'!$AB$5:$AB$2004,">0",'سجل التحفيز'!$B$5:$B$2004,B11)>0,COUNT(V$4:V10)+1,"")) | W11: =IF(B11="","",IF(COUNTIFS('سجل التحفيز'!$AC$5:$AC$2004,">0",'سجل التحفيز'!$B$5:$B$2004,B11)>0,COUNT(W$4:W10)+1,"")) | X11: =IF(B11="","",IF(COUNTIFS('سجل التحفيز'!$AD$5:$AD$2004,">0",'سجل التحفيز'!$B$5:$B$2004,B11)>0,COUNT(X$4:X10)+1,"")) | Y11: =IF(B11="","",IF(COUNTIFS('سجل التحفيز'!$AE$5:$AE$2004,">0",'سجل التحفيز'!$B$5:$B$2004,B11)>0,COUNT(Y$4:Y10)+1,""))
H12: =IF(B12="","",COUNTIFS('سجل التحفيز'!$B$5:$B$2004,B12,'سجل التحفيز'!$R$5:$R$2004,الإعدادات!$B$4)) | I12: =IF(B12="","",COUNTIFS('سجل التحفيز'!$B$5:$B$2004,B12,'سجل التحفيز'!$R$5:$R$2004,الإعدادات!$B$4,'سجل التحفيز'!$Q$5:$Q$2004,"الفصل الأول",'سجل التحفيز'!$D$5:$D$2004,"ذهبي")) | J12: =IF(B12="","",COUNTIFS('سجل التحفيز'!$B$5:$B$2004,B12,'سجل التحفيز'!$R$5:$R$2004,الإعدادات!$B$4,'سجل التحفيز'!$Q$5:$Q$2004,"الفصل الثاني",'سجل التحفيز'!$D$5:$D$2004,"ذهبي")) | K12: =IF(B12="","",COUNTIFS('سجل التحفيز'!$B$5:$B$2004,B12,'سجل التحفيز'!$R$5:$R$2004,الإعدادات!$B$4,'سجل التحفيز'!$D$5:$D$2004,"ذهبي")) | L12: =IF(B12="","",IF(G12="محرومة","محرومة - مخالفة",IF(K12>=5,"مستحقة ★","متبقي "&(5-K12)&" معايير"))) | N12: =IF(B12="","",IF(COUNTIFS('سجل التحفيز'!$T$5:$T$2004,">0",'سجل التحفيز'!$B$5:$B$2004,B12)>0,COUNT(N$4:N11)+1,"")) | O12: =IF(B12="","",IF(COUNTIFS('سجل التحفيز'!$U$5:$U$2004,">0",'سجل التحفيز'!$B$5:$B$2004,B12)>0,COUNT(O$4:O11)+1,"")) | P12: =IF(B12="","",IF(COUNTIFS('سجل التحفيز'!$V$5:$V$2004,">0",'سجل التحفيز'!$B$5:$B$2004,B12)>0,COUNT(P$4:P11)+1,"")) | Q12: =IF(B12="","",IF(COUNTIFS('سجل التحفيز'!$W$5:$W$2004,">0",'سجل التحفيز'!$B$5:$B$2004,B12)>0,COUNT(Q$4:Q11)+1,"")) | R12: =IF(B12="","",IF(COUNTIFS('سجل التحفيز'!$X$5:$X$2004,">0",'سجل التحفيز'!$B$5:$B$2004,B12)>0,COUNT(R$4:R11)+1,"")) | S12: =IF(B12="","",IF(COUNTIFS('سجل التحفيز'!$Y$5:$Y$2004,">0",'سجل التحفيز'!$B$5:$B$2004,B12)>0,COUNT(S$4:S11)+1,"")) | T12: =IF(B12="","",IF(COUNTIFS('سجل التحفيز'!$Z$5:$Z$2004,">0",'سجل التحفيز'!$B$5:$B$2004,B12)>0,COUNT(T$4:T11)+1,"")) | U12: =IF(B12="","",IF(COUNTIFS('سجل التحفيز'!$AA$5:$AA$2004,">0",'سجل التحفيز'!$B$5:$B$2004,B12)>0,COUNT(U$4:U11)+1,"")) | V12: =IF(B12="","",IF(COUNTIFS('سجل التحفيز'!$AB$5:$AB$2004,">0",'سجل التحفيز'!$B$5:$B$2004,B12)>0,COUNT(V$4:V11)+1,"")) | W12: =IF(B12="","",IF(COUNTIFS('سجل التحفيز'!$AC$5:$AC$2004,">0",'سجل التحفيز'!$B$5:$B$2004,B12)>0,COUNT(W$4:W11)+1,"")) | X12: =IF(B12="","",IF(COUNTIFS('سجل التحفيز'!$AD$5:$AD$2004,">0",'سجل التحفيز'!$B$5:$B$2004,B12)>0,COUNT(X$4:X11)+1,"")) | Y12: =IF(B12="","",IF(COUNTIFS('سجل التحفيز'!$AE$5:$AE$2004,">0",'سجل التحفيز'!$B$5:$B$2004,B12)>0,COUNT(Y$4:Y11)+1,""))
H13: =IF(B13="","",COUNTIFS('سجل التحفيز'!$B$5:$B$2004,B13,'سجل التحفيز'!$R$5:$R$2004,الإعدادات!$B$4)) | I13: =IF(B13="","",COUNTIFS('سجل التحفيز'!$B$5:$B$2004,B13,'سجل التحفيز'!$R$5:$R$2004,الإعدادات!$B$4,'سجل التحفيز'!$Q$5:$Q$2004,"الفصل الأول",'سجل التحفيز'!$D$5:$D$2004,"ذهبي")) | J13: =IF(B13="","",COUNTIFS('سجل التحفيز'!$B$5:$B$2004,B13,'سجل التحفيز'!$R$5:$R$2004,الإعدادات!$B$4,'سجل التحفيز'!$Q$5:$Q$2004,"الفصل الثاني",'سجل التحفيز'!$D$5:$D$2004,"ذهبي")) | K13: =IF(B13="","",COUNTIFS('سجل التحفيز'!$B$5:$B$2004,B13,'سجل التحفيز'!$R$5:$R$2004,الإعدادات!$B$4,'سجل التحفيز'!$D$5:$D$2004,"ذهبي")) | L13: =IF(B13="","",IF(G13="محرومة","محرومة - مخالفة",IF(K13>=5,"مستحقة ★","متبقي "&(5-K13)&" معايير"))) | N13: =IF(B13="","",IF(COUNTIFS('سجل التحفيز'!$T$5:$T$2004,">0",'سجل التحفيز'!$B$5:$B$2004,B13)>0,COUNT(N$4:N12)+1,"")) | O13: =IF(B13="","",IF(COUNTIFS('سجل التحفيز'!$U$5:$U$2004,">0",'سجل التحفيز'!$B$5:$B$2004,B13)>0,COUNT(O$4:O12)+1,"")) | P13: =IF(B13="","",IF(COUNTIFS('سجل التحفيز'!$V$5:$V$2004,">0",'سجل التحفيز'!$B$5:$B$2004,B13)>0,COUNT(P$4:P12)+1,"")) | Q13: =IF(B13="","",IF(COUNTIFS('سجل التحفيز'!$W$5:$W$2004,">0",'سجل التحفيز'!$B$5:$B$2004,B13)>0,COUNT(Q$4:Q12)+1,"")) | R13: =IF(B13="","",IF(COUNTIFS('سجل التحفيز'!$X$5:$X$2004,">0",'سجل التحفيز'!$B$5:$B$2004,B13)>0,COUNT(R$4:R12)+1,"")) | S13: =IF(B13="","",IF(COUNTIFS('سجل التحفيز'!$Y$5:$Y$2004,">0",'سجل التحفيز'!$B$5:$B$2004,B13)>0,COUNT(S$4:S12)+1,"")) | T13: =IF(B13="","",IF(COUNTIFS('سجل التحفيز'!$Z$5:$Z$2004,">0",'سجل التحفيز'!$B$5:$B$2004,B13)>0,COUNT(T$4:T12)+1,"")) | U13: =IF(B13="","",IF(COUNTIFS('سجل التحفيز'!$AA$5:$AA$2004,">0",'سجل التحفيز'!$B$5:$B$2004,B13)>0,COUNT(U$4:U12)+1,"")) | V13: =IF(B13="","",IF(COUNTIFS('سجل التحفيز'!$AB$5:$AB$2004,">0",'سجل التحفيز'!$B$5:$B$2004,B13)>0,COUNT(V$4:V12)+1,"")) | W13: =IF(B13="","",IF(COUNTIFS('سجل التحفيز'!$AC$5:$AC$2004,">0",'سجل التحفيز'!$B$5:$B$2004,B13)>0,COUNT(W$4:W12)+1,"")) | X13: =IF(B13="","",IF(COUNTIFS('سجل التحفيز'!$AD$5:$AD$2004,">0",'سجل التحفيز'!$B$5:$B$2004,B13)>0,COUNT(X$4:X12)+1,"")) | Y13: =IF(B13="","",IF(COUNTIFS('سجل التحفيز'!$AE$5:$AE$2004,">0",'سجل التحفيز'!$B$5:$B$2004,B13)>0,COUNT(Y$4:Y12)+1,""))
H14: =IF(B14="","",COUNTIFS('سجل التحفيز'!$B$5:$B$2004,B14,'سجل التحفيز'!$R$5:$R$2004,الإعدادات!$B$4)) | I14: =IF(B14="","",COUNTIFS('سجل التحفيز'!$B$5:$B$2004,B14,'سجل التحفيز'!$R$5:$R$2004,الإعدادات!$B$4,'سجل التحفيز'!$Q$5:$Q$2004,"الفصل الأول",'سجل التحفيز'!$D$5:$D$2004,"ذهبي")) | J14: =IF(B14="","",COUNTIFS('سجل التحفيز'!$B$5:$B$2004,B14,'سجل التحفيز'!$R$5:$R$2004,الإعدادات!$B$4,'سجل التحفيز'!$Q$5:$Q$2004,"الفصل الثاني",'سجل التحفيز'!$D$5:$D$2004,"ذهبي")) | K14: =IF(B14="","",COUNTIFS('سجل التحفيز'!$B$5:$B$2004,B14,'سجل التحفيز'!$R$5:$R$2004,الإعدادات!$B$4,'سجل التحفيز'!$D$5:$D$2004,"ذهبي")) | L14: =IF(B14="","",IF(G14="محرومة","محرومة - مخالفة",IF(K14>=5,"مستحقة ★","متبقي "&(5-K14)&" معايير"))) | N14: =IF(B14="","",IF(COUNTIFS('سجل التحفيز'!$T$5:$T$2004,">0",'سجل التحفيز'!$B$5:$B$2004,B14)>0,COUNT(N$4:N13)+1,"")) | O14: =IF(B14="","",IF(COUNTIFS('سجل التحفيز'!$U$5:$U$2004,">0",'سجل التحفيز'!$B$5:$B$2004,B14)>0,COUNT(O$4:O13)+1,"")) | P14: =IF(B14="","",IF(COUNTIFS('سجل التحفيز'!$V$5:$V$2004,">0",'سجل التحفيز'!$B$5:$B$2004,B14)>0,COUNT(P$4:P13)+1,"")) | Q14: =IF(B14="","",IF(COUNTIFS('سجل التحفيز'!$W$5:$W$2004,">0",'سجل التحفيز'!$B$5:$B$2004,B14)>0,COUNT(Q$4:Q13)+1,"")) | R14: =IF(B14="","",IF(COUNTIFS('سجل التحفيز'!$X$5:$X$2004,">0",'سجل التحفيز'!$B$5:$B$2004,B14)>0,COUNT(R$4:R13)+1,"")) | S14: =IF(B14="","",IF(COUNTIFS('سجل التحفيز'!$Y$5:$Y$2004,">0",'سجل التحفيز'!$B$5:$B$2004,B14)>0,COUNT(S$4:S13)+1,"")) | T14: =IF(B14="","",IF(COUNTIFS('سجل التحفيز'!$Z$5:$Z$2004,">0",'سجل التحفيز'!$B$5:$B$2004,B14)>0,COUNT(T$4:T13)+1,"")) | U14: =IF(B14="","",IF(COUNTIFS('سجل التحفيز'!$AA$5:$AA$2004,">0",'سجل التحفيز'!$B$5:$B$2004,B14)>0,COUNT(U$4:U13)+1,"")) | V14: =IF(B14="","",IF(COUNTIFS('سجل التحفيز'!$AB$5:$AB$2004,">0",'سجل التحفيز'!$B$5:$B$2004,B14)>0,COUNT(V$4:V13)+1,"")) | W14: =IF(B14="","",IF(COUNTIFS('سجل التحفيز'!$AC$5:$AC$2004,">0",'سجل التحفيز'!$B$5:$B$2004,B14)>0,COUNT(W$4:W13)+1,"")) | X14: =IF(B14="","",IF(COUNTIFS('سجل التحفيز'!$AD$5:$AD$2004,">0",'سجل التحفيز'!$B$5:$B$2004,B14)>0,COUNT(X$4:X13)+1,"")) | Y14: =IF(B14="","",IF(COUNTIFS('سجل التحفيز'!$AE$5:$AE$2004,">0",'سجل التحفيز'!$B$5:$B$2004,B14)>0,COUNT(Y$4:Y13)+1,""))
H15: =IF(B15="","",COUNTIFS('سجل التحفيز'!$B$5:$B$2004,B15,'سجل التحفيز'!$R$5:$R$2004,الإعدادات!$B$4)) | I15: =IF(B15="","",COUNTIFS('سجل التحفيز'!$B$5:$B$2004,B15,'سجل التحفيز'!$R$5:$R$2004,الإعدادات!$B$4,'سجل التحفيز'!$Q$5:$Q$2004,"الفصل الأول",'سجل التحفيز'!$D$5:$D$2004,"ذهبي")) | J15: =IF(B15="","",COUNTIFS('سجل التحفيز'!$B$5:$B$2004,B15,'سجل التحفيز'!$R$5:$R$2004,الإعدادات!$B$4,'سجل التحفيز'!$Q$5:$Q$2004,"الفصل الثاني",'سجل التحفيز'!$D$5:$D$2004,"ذهبي")) | K15: =IF(B15="","",COUNTIFS('سجل التحفيز'!$B$5:$B$2004,B15,'سجل التحفيز'!$R$5:$R$2004,الإعدادات!$B$4,'سجل التحفيز'!$D$5:$D$2004,"ذهبي")) | L15: =IF(B15="","",IF(G15="محرومة","محرومة - مخالفة",IF(K15>=5,"مستحقة ★","متبقي "&(5-K15)&" معايير"))) | N15: =IF(B15="","",IF(COUNTIFS('سجل التحفيز'!$T$5:$T$2004,">0",'سجل التحفيز'!$B$5:$B$2004,B15)>0,COUNT(N$4:N14)+1,"")) | O15: =IF(B15="","",IF(COUNTIFS('سجل التحفيز'!$U$5:$U$2004,">0",'سجل التحفيز'!$B$5:$B$2004,B15)>0,COUNT(O$4:O14)+1,"")) | P15: =IF(B15="","",IF(COUNTIFS('سجل التحفيز'!$V$5:$V$2004,">0",'سجل التحفيز'!$B$5:$B$2004,B15)>0,COUNT(P$4:P14)+1,"")) | Q15: =IF(B15="","",IF(COUNTIFS('سجل التحفيز'!$W$5:$W$2004,">0",'سجل التحفيز'!$B$5:$B$2004,B15)>0,COUNT(Q$4:Q14)+1,"")) | R15: =IF(B15="","",IF(COUNTIFS('سجل التحفيز'!$X$5:$X$2004,">0",'سجل التحفيز'!$B$5:$B$2004,B15)>0,COUNT(R$4:R14)+1,"")) | S15: =IF(B15="","",IF(COUNTIFS('سجل التحفيز'!$Y$5:$Y$2004,">0",'سجل التحفيز'!$B$5:$B$2004,B15)>0,COUNT(S$4:S14)+1,"")) | T15: =IF(B15="","",IF(COUNTIFS('سجل التحفيز'!$Z$5:$Z$2004,">0",'سجل التحفيز'!$B$5:$B$2004,B15)>0,COUNT(T$4:T14)+1,"")) | U15: =IF(B15="","",IF(COUNTIFS('سجل التحفيز'!$AA$5:$AA$2004,">0",'سجل التحفيز'!$B$5:$B$2004,B15)>0,COUNT(U$4:U14)+1,"")) | V15: =IF(B15="","",IF(COUNTIFS('سجل التحفيز'!$AB$5:$AB$2004,">0",'سجل التحفيز'!$B$5:$B$2004,B15)>0,COUNT(V$4:V14)+1,"")) | W15: =IF(B15="","",IF(COUNTIFS('سجل التحفيز'!$AC$5:$AC$2004,">0",'سجل التحفيز'!$B$5:$B$2004,B15)>0,COUNT(W$4:W14)+1,"")) | X15: =IF(B15="","",IF(COUNTIFS('سجل التحفيز'!$AD$5:$AD$2004,">0",'سجل التحفيز'!$B$5:$B$2004,B15)>0,COUNT(X$4:X14)+1,"")) | Y15: =IF(B15="","",IF(COUNTIFS('سجل التحفيز'!$AE$5:$AE$2004,">0",'سجل التحفيز'!$B$5:$B$2004,B15)>0,COUNT(Y$4:Y14)+1,""))
H16: =IF(B16="","",COUNTIFS('سجل التحفيز'!$B$5:$B$2004,B16,'سجل التحفيز'!$R$5:$R$2004,الإعدادات!$B$4)) | I16: =IF(B16="","",COUNTIFS('سجل التحفيز'!$B$5:$B$2004,B16,'سجل التحفيز'!$R$5:$R$2004,الإعدادات!$B$4,'سجل التحفيز'!$Q$5:$Q$2004,"الفصل الأول",'سجل التحفيز'!$D$5:$D$2004,"ذهبي")) | J16: =IF(B16="","",COUNTIFS('سجل التحفيز'!$B$5:$B$2004,B16,'سجل التحفيز'!$R$5:$R$2004,الإعدادات!$B$4,'سجل التحفيز'!$Q$5:$Q$2004,"الفصل الثاني",'سجل التحفيز'!$D$5:$D$2004,"ذهبي")) | K16: =IF(B16="","",COUNTIFS('سجل التحفيز'!$B$5:$B$2004,B16,'سجل التحفيز'!$R$5:$R$2004,الإعدادات!$B$4,'سجل التحفيز'!$D$5:$D$2004,"ذهبي")) | L16: =IF(B16="","",IF(G16="محرومة","محرومة - مخالفة",IF(K16>=5,"مستحقة ★","متبقي "&(5-K16)&" معايير"))) | N16: =IF(B16="","",IF(COUNTIFS('سجل التحفيز'!$T$5:$T$2004,">0",'سجل التحفيز'!$B$5:$B$2004,B16)>0,COUNT(N$4:N15)+1,"")) | O16: =IF(B16="","",IF(COUNTIFS('سجل التحفيز'!$U$5:$U$2004,">0",'سجل التحفيز'!$B$5:$B$2004,B16)>0,COUNT(O$4:O15)+1,"")) | P16: =IF(B16="","",IF(COUNTIFS('سجل التحفيز'!$V$5:$V$2004,">0",'سجل التحفيز'!$B$5:$B$2004,B16)>0,COUNT(P$4:P15)+1,"")) | Q16: =IF(B16="","",IF(COUNTIFS('سجل التحفيز'!$W$5:$W$2004,">0",'سجل التحفيز'!$B$5:$B$2004,B16)>0,COUNT(Q$4:Q15)+1,"")) | R16: =IF(B16="","",IF(COUNTIFS('سجل التحفيز'!$X$5:$X$2004,">0",'سجل التحفيز'!$B$5:$B$2004,B16)>0,COUNT(R$4:R15)+1,"")) | S16: =IF(B16="","",IF(COUNTIFS('سجل التحفيز'!$Y$5:$Y$2004,">0",'سجل التحفيز'!$B$5:$B$2004,B16)>0,COUNT(S$4:S15)+1,"")) | T16: =IF(B16="","",IF(COUNTIFS('سجل التحفيز'!$Z$5:$Z$2004,">0",'سجل التحفيز'!$B$5:$B$2004,B16)>0,COUNT(T$4:T15)+1,"")) | U16: =IF(B16="","",IF(COUNTIFS('سجل التحفيز'!$AA$5:$AA$2004,">0",'سجل التحفيز'!$B$5:$B$2004,B16)>0,COUNT(U$4:U15)+1,"")) | V16: =IF(B16="","",IF(COUNTIFS('سجل التحفيز'!$AB$5:$AB$2004,">0",'سجل التحفيز'!$B$5:$B$2004,B16)>0,COUNT(V$4:V15)+1,"")) | W16: =IF(B16="","",IF(COUNTIFS('سجل التحفيز'!$AC$5:$AC$2004,">0",'سجل التحفيز'!$B$5:$B$2004,B16)>0,COUNT(W$4:W15)+1,"")) | X16: =IF(B16="","",IF(COUNTIFS('سجل التحفيز'!$AD$5:$AD$2004,">0",'سجل التحفيز'!$B$5:$B$2004,B16)>0,COUNT(X$4:X15)+1,"")) | Y16: =IF(B16="","",IF(COUNTIFS('سجل التحفيز'!$AE$5:$AE$2004,">0",'سجل التحفيز'!$B$5:$B$2004,B16)>0,COUNT(Y$4:Y15)+1,""))
... H304: =IF(B304="","",COUNTIFS('سجل التحفيز'!$B$5:$B$2004,B304,'سجل التحفيز'!$R$5:$R$2004,الإعدادات!$B$4)) | I304: =IF(B304="","",COUNTIFS('سجل التحفيز'!$B$5:$B$2004,B304,'سجل التحفيز'!$R$5:$R$2004,الإعدادات!$B$4,'سجل التحفيز'!$Q$5:$Q$2004,"الفصل الأول",'سجل التحفيز'!$D$5:$D$2004,"ذهبي")) | J304: =IF(B304="","",COUNTIFS('سجل التحفيز'!$B$5:$B$2004,B304,'سجل التحفيز'!$R$5:$R$2004,الإعدادات!$B$4,'سجل التحفيز'!$Q$5:$Q$2004,"الفصل الثاني",'سجل التحفيز'!$D$5:$D$2004,"ذهبي")) | K304: =IF(B304="","",COUNTIFS('سجل التحفيز'!$B$5:$B$2004,B304,'سجل التحفيز'!$R$5:$R$2004,الإعدادات!$B$4,'سجل التحفيز'!$D$5:$D$2004,"ذهبي")) | L304: =IF(B304="","",IF(G304="محرومة","محرومة - مخالفة",IF(K304>=5,"مستحقة ★","متبقي "&(5-K304)&" معايير"))) | N304: =IF(B304="","",IF(COUNTIFS('سجل التحفيز'!$T$5:$T$2004,">0",'سجل التحفيز'!$B$5:$B$2004,B304)>0,COUNT(N$4:N303)+1,"")) | O304: =IF(B304="","",IF(COUNTIFS('سجل التحفيز'!$U$5:$U$2004,">0",'سجل التحفيز'!$B$5:$B$2004,B304)>0,COUNT(O$4:O303)+1,"")) | P304: =IF(B304="","",IF(COUNTIFS('سجل التحفيز'!$V$5:$V$2004,">0",'سجل التحفيز'!$B$5:$B$2004,B304)>0,COUNT(P$4:P303)+1,"")) | Q304: =IF(B304="","",IF(COUNTIFS('سجل التحفيز'!$W$5:$W$2004,">0",'سجل التحفيز'!$B$5:$B$2004,B304)>0,COUNT(Q$4:Q303)+1,"")) | R304: =IF(B304="","",IF(COUNTIFS('سجل التحفيز'!$X$5:$X$2004,">0",'سجل التحفيز'!$B$5:$B$2004,B304)>0,COUNT(R$4:R303)+1,"")) | S304: =IF(B304="","",IF(COUNTIFS('سجل التحفيز'!$Y$5:$Y$2004,">0",'سجل التحفيز'!$B$5:$B$2004,B304)>0,COUNT(S$4:S303)+1,"")) | T304: =IF(B304="","",IF(COUNTIFS('سجل التحفيز'!$Z$5:$Z$2004,">0",'سجل التحفيز'!$B$5:$B$2004,B304)>0,COUNT(T$4:T303)+1,"")) | U304: =IF(B304="","",IF(COUNTIFS('سجل التحفيز'!$AA$5:$AA$2004,">0",'سجل التحفيز'!$B$5:$B$2004,B304)>0,COUNT(U$4:U303)+1,"")) | V304: =IF(B304="","",IF(COUNTIFS('سجل التحفيز'!$AB$5:$AB$2004,">0",'سجل التحفيز'!$B$5:$B$2004,B304)>0,COUNT(V$4:V303)+1,"")) | W304: =IF(B304="","",IF(COUNTIFS('سجل التحفيز'!$AC$5:$AC$2004,">0",'سجل التحفيز'!$B$5:$B$2004,B304)>0,COUNT(W$4:W303)+1,"")) | X304: =IF(B304="","",IF(COUNTIFS('سجل التحفيز'!$AD$5:$AD$2004,">0",'سجل التحفيز'!$B$5:$B$2004,B304)>0,COUNT(X$4:X303)+1,"")) | Y304: =IF(B304="","",IF(COUNTIFS('سجل التحفيز'!$AE$5:$AE$2004,">0",'سجل التحفيز'!$B$5:$B$2004,B304)>0,COUNT(Y$4:Y303)+1,""))

Sheet تقرير الفصل الأول
A1: تقرير الفصل الأول
A2: يشمل: سبتمبر – أكتوبر – نوفمبر – ديسمبر — للسنة الدراسية الحالية (الخلية C4).
B4: السنة الدراسية | C4: =الإعدادات!$B$4 | E4: ="فترة التقرير: "&IF(C5="سنوي","السنة الدراسية "&C4,IF(C5="شهري","شهر "&C6&" — "&C4,C7&" — "&C4))
B5: نوع التقرير | C5: فصلي
B6: الشهر | C6: — | E6: ="مديرة المدرسة: "&الإعدادات!$B$39&" · النائبة الأكاديمية: "&الإعدادات!$B$40&" · النائبة الإدارية: "&الإعدادات!$B$41
B7: الفصل الدراسي | C7: الفصل الأول
B9: عدد التكريمات | C9: موظفات مُكرَّمات | D9: معايير ذهبية | E9: معايير أساسية | F9: القيمة المادية (ر.ق) | G9: مستحقات أمري تدللي (السنة)
B10: =COUNT('سجل التحفيز'!$U$5:$U$2004) | C10: =COUNT(الموظفات!$O$5:$O$304) | D10: =COUNTIFS('سجل التحفيز'!$U$5:$U$2004,">0",'سجل التحفيز'!$D$5:$D$2004,"ذهبي") | E10: =COUNTIFS('سجل التحفيز'!$U$5:$U$2004,">0",'سجل التحفيز'!$D$5:$D$2004,"أساسي") | F10: =SUMIFS('سجل التحفيز'!$G$5:$G$2004,'سجل التحفيز'!$U$5:$U$2004,">0") | G10: =COUNTIF(الموظفات!$L$5:$L$304,"مستحقة ★")
B12: التكريمات حسب المجال
